Workbook
Name ACTION: #REF!
Name ACTION: #REF!

Sheet Cover
B2: TEST REPORT DOCUMENT
A4: Project Name | B4: EnglishLab | E4: Creator | F4: phongdx
A5: Project Code | B5: SEP490_G23 | E5: Issue Date | F5: 2026-07-28
A6: Document Code | B6: =B5&"_"&"XXX"&"_"&"vx.x" | E6: Version | F6: v4.0
A9: Record of change
A10: Effective Date | B10: Version | C10: Change Item | D10: *A,D,M | E10: Change description | F10: Reference
A11: 2026-07-28 | B11: v4.0 | C11: Integration Test design for EnglishLab backend | D11: A | E11: v4 executed 3 rounds on 2026-07-28 against http://localhost:8080; Round statuses filled by live API integration runner | F11: SRS Report3; source tree; srs-usecase-diagram-map.md

Sheet Test Cases
D1: TEST CASE LIST
B3: Project Name | D3: =Cover!B4
B4: Project Code | D4: =Cover!B5
B5: Test Environment Setup Description | D5: 1. Server: Spring Boot 4 + JDK 21 (@SpringBootTest + MockMvc) 2. Database: PostgreSQL with migrations applied 3. Web Browser: N/A for API Integration Tests (optional Postman/curl) 4. JWT security enabled; roles seeded 5. External PayOS / Mail / Gemini / Lark stubbed or sandbox
B8: No | C8: Function Name | D8: Sheet Name | E8: Description | F8: Pre-Condition
B9: 1 | C9: AuthController | D9: IT - Auth | E9: Integrate AuthController with AuthService and persistence for register/verify/login/OTP reset. | F9: DB up; roles seeded; target sheet `IT - Auth` exists; external systems stubbed as needed for this module.
B10: 2 | C10: UserController | D10: IT - User | E10: Integrate UserController profile/avatar/password with UserService and UserRepository. | F10: DB up; roles seeded; target sheet `IT - User` exists; external systems stubbed as needed for this module.
B11: 3 | C11: StudentNotificationController | D11: IT - Notif | E11: Integrate notification preferences and AppNotification list/read flows. | F11: DB up; roles seeded; target sheet `IT - Notif` exists; external systems stubbed as needed for this module.
B12: 4 | C12: StudentCommerceController | D12: IT - Commerce | E12: Integrate StudentCommerceController cart/wishlist with StudentCommerceService persistence. | F12: DB up; roles seeded; target sheet `IT - Commerce` exists; external systems stubbed as needed for this module.
B13: 5 | C13: StudentPaymentController | D13: IT - Payment | E13: Integrate payment link/quote, payment_orders persistence and PayOS webhook side effects. | F13: DB up; roles seeded; target sheet `IT - Payment` exists; external systems stubbed as needed for this module.
B14: 6 | C14: PublicOnlineCourseController | D14: IT - Course | E14: Integrate public catalog and learner content/progress through OnlineCourseService. | F14: DB up; roles seeded; target sheet `IT - Course` exists; external systems stubbed as needed for this module.
B15: 7 | C15: CourseDiscussionController | D15: IT - Discuss | E15: Integrate discussion create/reply/report and CM moderation through discussion services. | F15: DB up; roles seeded; target sheet `IT - Discuss` exists; external systems stubbed as needed for this module.
B16: 8 | C16: ContentManagerOnlineCourseController | D16: IT - Content | E16: Integrate Content Manager online course CRUD/publish/version/category flows. | F16: DB up; roles seeded; target sheet `IT - Content` exists; external systems stubbed as needed for this module.
B17: 9 | C17: LearningPackageManagementController | D17: IT - Package | E17: Integrate CM package/bundle management through LearningPackageManagementService. | F17: DB up; roles seeded; target sheet `IT - Package` exists; external systems stubbed as needed for this module.
B18: 10 | C18: ContentManagerCurriculumController | D18: IT - Curriculum | E18: Integrate curriculum programs/units, exercise bank, rubrics and learning paths. | F18: DB up; roles seeded; target sheet `IT - Curriculum` exists; external systems stubbed as needed for this module.
B19: 11 | C19: ManagerEnrollmentController | D19: IT - EnrollReq | E19: Integrate learner enrollment requests and staff processing via EnrollmentRequestService. | F19: DB up; roles seeded; target sheet `IT - EnrollReq` exists; external systems stubbed as needed for this module.
B20: 12 | C20: TrainingManagerClassroomController | D20: IT - Classroom | E20: Integrate public offerings and TM enrollment/teacher operations via ClassroomOfferingService. | F20: DB up; roles seeded; target sheet `IT - Classroom` exists; external systems stubbed as needed for this module.
... B32: 24 | C32: StudentClassroomController | D32: IT - Notes | E32: Integrate learner lesson notes CRUD through LearnerLearningExperienceService. | F32: DB up; roles seeded; target sheet `IT - Notes` exists; external systems stubbed as needed for this module.

Sheet Test Statistics
B1: TEST STATISTICS
B3: Project Name | C3: =Cover!B4 | E3: Creator | F3: phongdx
B4: Project Code | C4: =Cover!B5 | E4: Reviewer/Approver
B5: Document Code | C5: =C4&"_"&"Test Report"&"_"&"vx.x" | E5: Issue Date | H5: 2026-07-28
B6: Notes | C6: Release Integration Test pack includes 24 modules: AUTH, USER, NOTIF, COMMERCE, PAYMENT, COURSE, DISCUSS, CONTENT, PACKAGE, CURRICULUM, ENROLLREQ, CLASS, LEARNERCLS, TEACH, QUIZ, ASSESS, SUPPORT, ADMIN, LARK, INFRA, REPORT, PROPOSAL, DISPUTE, NOTES
B10: No | C10: Module code | D10: Passed | E10: Failed | F10: Pending | G10: N/A | H10: Number of test cases
B11: 1 | C11: ='IT - Auth'!B2 | D11: ='IT - Auth'!B6 | E11: ='IT - Auth'!C6 | F11: ='IT - Auth'!D6 | G11: ='IT - Auth'!E6 | H11: ='IT - Auth'!B4
B12: 2 | C12: ='IT - User'!B2 | D12: ='IT - User'!B6 | E12: ='IT - User'!C6 | F12: ='IT - User'!D6 | G12: ='IT - User'!E6 | H12: ='IT - User'!B4
B13: 3 | C13: ='IT - Notif'!B2 | D13: ='IT - Notif'!B6 | E13: ='IT - Notif'!C6 | F13: ='IT - Notif'!D6 | G13: ='IT - Notif'!E6 | H13: ='IT - Notif'!B4
B14: 4 | C14: ='IT - Commerce'!B2 | D14: ='IT - Commerce'!B6 | E14: ='IT - Commerce'!C6 | F14: ='IT - Commerce'!D6 | G14: ='IT - Commerce'!E6 | H14: ='IT - Commerce'!B4
B15: 5 | C15: ='IT - Payment'!B2 | D15: ='IT - Payment'!B6 | E15: ='IT - Payment'!C6 | F15: ='IT - Payment'!D6 | G15: ='IT - Payment'!E6 | H15: ='IT - Payment'!B4
B16: 6 | C16: ='IT - Course'!B2 | D16: ='IT - Course'!B6 | E16: ='IT - Course'!C6 | F16: ='IT - Course'!D6 | G16: ='IT - Course'!E6 | H16: ='IT - Course'!B4
B17: 7 | C17: ='IT - Discuss'!B2 | D17: ='IT - Discuss'!B6 | E17: ='IT - Discuss'!C6 | F17: ='IT - Discuss'!D6 | G17: ='IT - Discuss'!E6 | H17: ='IT - Discuss'!B4
B18: 8 | C18: ='IT - Content'!B2 | D18: ='IT - Content'!B6 | E18: ='IT - Content'!C6 | F18: ='IT - Content'!D6 | G18: ='IT - Content'!E6 | H18: ='IT - Content'!B4
B19: 9 | C19: ='IT - Package'!B2 | D19: ='IT - Package'!B6 | E19: ='IT - Package'!C6 | F19: ='IT - Package'!D6 | G19: ='IT - Package'!E6 | H19: ='IT - Package'!B4
B20: 10 | C20: ='IT - Curriculum'!B2 | D20: ='IT - Curriculum'!B6 | E20: ='IT - Curriculum'!C6 | F20: ='IT - Curriculum'!D6 | G20: ='IT - Curriculum'!E6 | H20: ='IT - Curriculum'!B4
B21: 11 | C21: ='IT - EnrollReq'!B2 | D21: ='IT - EnrollReq'!B6 | E21: ='IT - EnrollReq'!C6 | F21: ='IT - EnrollReq'!D6 | G21: ='IT - EnrollReq'!E6 | H21: ='IT - EnrollReq'!B4
B22: 12 | C22: ='IT - Classroom'!B2 | D22: ='IT - Classroom'!B6 | E22: ='IT - Classroom'!C6 | F22: ='IT - Classroom'!D6 | G22: ='IT - Classroom'!E6 | H22: ='IT - Classroom'!B4
B23: 13 | C23: ='IT - LearnerCls'!B2 | D23: ='IT - LearnerCls'!B6 | E23: ='IT - LearnerCls'!C6 | F23: ='IT - LearnerCls'!D6 | G23: ='IT - LearnerCls'!E6 | H23: ='IT - LearnerCls'!B4
B24: 14 | C24: ='IT - Teacher'!B2 | D24: ='IT - Teacher'!B6 | E24: ='IT - Teacher'!C6 | F24: ='IT - Teacher'!D6 | G24: ='IT - Teacher'!E6 | H24: ='IT - Teacher'!B4
B25: 15 | C25: ='IT - Quiz'!B2 | D25: ='IT - Quiz'!B6 | E25: ='IT - Quiz'!C6 | F25: ='IT - Quiz'!D6 | G25: ='IT - Quiz'!E6 | H25: ='IT - Quiz'!B4
B26: 16 | C26: ='IT - Assess'!B2 | D26: ='IT - Assess'!B6 | E26: ='IT - Assess'!C6 | F26: ='IT - Assess'!D6 | G26: ='IT - Assess'!E6 | H26: ='IT - Assess'!B4
B27: 17 | C27: ='IT - Support'!B2 | D27: ='IT - Support'!B6 | E27: ='IT - Support'!C6 | F27: ='IT - Support'!D6 | G27: ='IT - Support'!E6 | H27: ='IT - Support'!B4
B28: 18 | C28: ='IT - Admin'!B2 | D28: ='IT - Admin'!B6 | E28: ='IT - Admin'!C6 | F28: ='IT - Admin'!D6 | G28: ='IT - Admin'!E6 | H28: ='IT - Admin'!B4
B29: 19 | C29: ='IT - Lark'!B2 | D29: ='IT - Lark'!B6 | E29: ='IT - Lark'!C6 | F29: ='IT - Lark'!D6 | G29: ='IT - Lark'!E6 | H29: ='IT - Lark'!B4
B30: 20 | C30: ='IT - Infra'!B2 | D30: ='IT - Infra'!B6 | E30: ='IT - Infra'!C6 | F30: ='IT - Infra'!D6 | G30: ='IT - Infra'!E6 | H30: ='IT - Infra'!B4
B31: 21 | C31: ='IT - Report'!B2 | D31: ='IT - Report'!B6 | E31: ='IT - Report'!C6 | F31: ='IT - Report'!D6 | G31: ='IT - Report'!E6 | H31: ='IT - Report'!B4
B32: 22 | C32: ='IT - Proposal'!B2 | D32: ='IT - Proposal'!B6 | E32: ='IT - Proposal'!C6 | F32: ='IT - Proposal'!D6 | G32: ='IT - Proposal'!E6 | H32: ='IT - Proposal'!B4
B33: 23 | C33: ='IT - Dispute'!B2 | D33: ='IT - Dispute'!B6 | E33: ='IT - Dispute'!C6 | F33: ='IT - Dispute'!D6 | G33: ='IT - Dispute'!E6 | H33: ='IT - Dispute'!B4
B34: 24 | C34: ='IT - Notes'!B2 | D34: ='IT - Notes'!B6 | E34: ='IT - Notes'!C6 | F34: ='IT - Notes'!D6 | G34: ='IT - Notes'!E6 | H34: ='IT - Notes'!B4
C36: Sub total | D36: =SUM(D11:D34) | E36: =SUM(E11:E34) | F36: =SUM(F11:F34) | G36: =SUM(G11:G34) | H36: =SUM(H11:H34)
C38: Test coverage | E38: =IF((H36-G36)=0,0,(D36+E36)*100/(H36-G36)) | F38: %
C39: Test successful coverage | E39: =IF((H36-G36)=0,0,D36*100/(H36-G36)) | F39: %

Sheet IT - Auth
A2: Feature | B2: AuthController | R2: Passed
A3: Test requirement | B3: Integrate AuthController with AuthService and persistence for register/verify/login/OTP reset. | R3: Failed
A4: Number of TCs | B4: =COUNTIF(A11:A1000,"IT_*") | R4: Pending
A5: Testing Round | B5: Passed | C5: Failed | D5: Pending | E5: N/A | R5: N/A
A6: Round 1 | B6: =COUNTIF($F11:$F998,B5) | C6: =COUNTIF($F11:$F998,C5) | D6: =COUNTIF($F11:$F998,D5) | E6: =COUNTIF($F11:$F998,E5)
A7: Round 2 | B7: =COUNTIF($I11:$I998,B5) | C7: =COUNTIF($I11:$I998,C5) | D7: =COUNTIF($I11:$I998,D5) | E7: =COUNTIF($I11:$I998,E5)
A8: Round 3 | B8: =COUNTIF($L11:$L998,B5) | C8: =COUNTIF($L11:$L998,C5) | D8: =COUNTIF($L11:$L998,D5) | E8: =COUNTIF($L11:$L998,E5)
A10: Test Case ID | B10: Test Case Description | C10: Test Case Procedure | D10: Expected Results | E10: Pre-conditions | F10: Round 1 | G10: Test date | H10: Tester | I10: Round 2 | J10: Test date | K10: Tester | L10: Round 3 | M10: Test date | N10: Tester | O10: Note
A11: Register & verify
A12: IT_AUTH_01 | B12: Verify registering an account through AuthController persists user and verification token via AuthService. | C12: 1. Call POST /api/auth/register via MockMvc with a unique email, password and fullName. 2. AuthController.register() delegates to AuthService.register(). 3. AuthService creates the account through UserRepository.save() and stores a verification OTP through AuthTokenRepository. 4. Query the users and auth_tokens tables for the new email. | D12: Response is 200/201 with a success message. One users row is inserted with hashed password (not plaintext). One verification auth_tokens row is linked to that user. No access token is required for this call. | E12: Database is available; email is unused; mail sender is stubbed. | F12: Passed | G12: 2026-07-28 | H12: phongdx | I12: Passed | J12: 2026-07-28 | K12: phongdx | L12: Passed | M12: 2026-07-28 | N12: phongdx | O12: register HTTP 200
A13: IT_AUTH_02 | B13: Verify duplicate registration is rejected by AuthService without inserting a second users row. | C13: 1. Seed an existing LEARNER in users. 2. Call POST /api/auth/register via MockMvc with the same email. 3. AuthController delegates to AuthService.register() which checks UserRepository before insert. 4. Count users rows for that email. | D13: Response is 4xx with a duplicate-email business error. Exactly one users row remains for the email. No extra verification token is created for a second account. | E13: An active user with the target email already exists. | F13: Passed | G13: 2026-07-28 | H13: phongdx | I13: Passed | J13: 2026-07-28 | K13: phongdx | L13: Passed | M13: 2026-07-28 | N13: phongdx | O13: duplicate register (negative) HTTP 400
A14: IT_AUTH_03 | B14: Verify email verification activates the account through AuthService and AuthTokenRepository. | C14: 1. Register a user and read the OTP from auth_tokens. 2. Call POST /api/auth/verify-email via MockMvc with email and OTP. 3. AuthController.verifyEmail() delegates to AuthService.verifyEmail(). 4. AuthService validates the token via AuthTokenRepository and updates the user via UserRepository. 5. Reload users and auth_tokens. | D14: Response is 200 OK. users.email_verified becomes true. Verification token is consumed/expired per AuthService rules. Subsequent login with the password succeeds. | E14: A pending verification user and valid OTP exist. | F14: Failed | G14: 2026-07-28 | H14: phongdx | I14: Failed | J14: 2026-07-28 | K14: phongdx | L14: Failed | M14: 2026-07-28 | N14: phongdx | O14: verify-email happy-path expected [200, 201] got 400: {"status":400,"message":"M? x?c th?c l? b?t bu?c"}
A15: IT_AUTH_04 | B15: Verify invalid OTP is rejected and leaves the user unverified. | C15: 1. Seed an unverified user with a real OTP in auth_tokens. 2. Call POST /api/auth/verify-email via MockMvc with a wrong OTP. 3. AuthService.verifyEmail() validates against AuthTokenRepository and must not update UserRepository verification flag. 4. Query users.email_verified. | D15: Response is 4xx. email_verified remains false. Account is not activated. | E15: An unverified user exists. | F15: Passed | G15: 2026-07-28 | H15: phongdx | I15: Passed | J15: 2026-07-28 | K15: phongdx | L15: Passed | M15: 2026-07-28 | N15: phongdx | O15: invalid OTP (negative) HTTP 400
A16: Login & security
A17: IT_AUTH_05 | B17: Verify login through AuthController returns a JWT accepted by the security filter and UserController. | C17: 1. Seed a verified LEARNER with a known password hash. 2. Call POST /api/auth/login via MockMvc. 3. AuthController.login() delegates to AuthService.login() which authenticates via UserRepository/UserDetails. 4. Call GET /api/user/me via MockMvc with Authorization Bearer accessToken. 5. JwtAuthenticationFilter authenticates the request before UserController.getCurrentUser(). | D17: Login response is 200 OK and contains accessToken plus user payload. GET /api/user/me returns 200 with the same email/id. JWT subject matches the authenticated user. | E17: A verified LEARNER account exists. | F17: Passed | G17: 2026-07-28 | H17: phongdx | I17: Passed | J17: 2026-07-28 | K17: phongdx | L17: Passed | M17: 2026-07-28 | N17: phongdx | O17: login + me HTTP 200
A18: IT_AUTH_06 | B18: Verify wrong password login fails in AuthService and issues no usable token. | C18: 1. Seed a verified user. 2. Call POST /api/auth/login via MockMvc with an incorrect password. 3. AuthService.login() rejects authentication before issuing JWT. | D18: Response is 401/403. No valid accessToken is returned. Protected endpoints remain inaccessible without a token. | E18: A verified user exists. | F18: Passed | G18: 2026-07-28 | H18: phongdx | I18: Passed | J18: 2026-07-28 | K18: phongdx | L18: Passed | M18: 2026-07-28 | N18: phongdx | O18: bad password (negative) HTTP 401
A19: IT_AUTH_07 | B19: Verify missing JWT is blocked by SecurityFilterChain before UserController executes. | C19: 1. Call GET /api/user/me via MockMvc without Authorization header. 2. Observe that JwtAuthenticationFilter / authorizeHttpRequests rejects the call before UserService is invoked. | D19: Response is 401 or 403. No UserResponse body is returned. Confirms controller-security integration. | E19: Spring Security configuration is active. | F19: Passed | G19: 2026-07-28 | H19: phongdx | I19: Passed | J19: 2026-07-28 | K19: phongdx | L19: Passed | M19: 2026-07-28 | N19: phongdx | O19: me without token (negative) HTTP 403
A20: Password recovery
A21: IT_AUTH_08 | B21: Verify forgot-password and reset-password flow updates credentials through AuthService. | C21: 1. Seed a verified user and capture the current password hash. 2. Call POST /api/auth/forgot-password via MockMvc. 3. AuthService creates a reset token via AuthTokenRepository. 4. Call POST /api/auth/reset-password via MockMvc with OTP and new password. 5. AuthService updates the hash via UserRepository.save(). 6. Login with the new password and attempt the old password. | D21: Forgot-password returns a generic success response. Reset succeeds and users.password hash changes. Login works only with the new password. | E21: Verified user exists; mail is stubbed. | F21: Passed | G21: 2026-07-28 | H21: phongdx | I21: Failed | J21: 2026-07-28 | K21: phongdx | L21: Passed | M21: 2026-07-28 | N21: phongdx | O21: forgot-password happy-path HTTP 200
A22: IT_AUTH_09 | B22: Verify invalid reset OTP does not change the password hash. | C22: 1. Seed a verified user and capture password hash. 2. Call POST /api/auth/reset-password via MockMvc with an invalid OTP. 3. AuthService.resetPassword() rejects via AuthTokenRepository validation. 4. Compare password hash in users. | D22: Response is 4xx. Password hash is unchanged. Old credentials still authenticate. | E22: A verified user exists. | F22: Failed | G22: 2026-07-28 | H22: phongdx | I22: Failed | J22: 2026-07-28 | K22: phongdx | L22: Failed | M22: 2026-07-28 | N22: phongdx | O22: forgot before reset 400: {"status":400,"message":"Vui l?ng ch? 54 gi?y tr??c khi g?i l?i OTP."}
A23: IT_AUTH_10 | B23: Verify resend-verification rotates or recreates a verification token through AuthService. | C23: 1. Seed an unverified user. 2. Call POST /api/auth/resend-verification via MockMvc. 3. AuthController delegates to AuthService which writes AuthTokenRepository. 4. Query auth_tokens for an active verification token. | D23: Response is 200 OK. An active verification token exists for the user. No account is marked verified by this call alone. | E23: An unverified user exists; mail is stubbed. | F23: Passed | G23: 2026-07-28 | H23: phongdx | I23: Passed | J23: 2026-07-28 | K23: phongdx | L23: Passed | M23: 2026-07-28 | N23: phongdx | O23: reset invalid OTP (negative) HTTP 400

Sheet IT - User
A2: Feature | B2: UserController | R2: Passed
A3: Test requirement | B3: Integrate UserController profile/avatar/password with UserService and UserRepository. | R3: Failed
A4: Number of TCs | B4: =COUNTIF(A11:A1000,"IT_*") | R4: Pending
A5: Testing Round | B5: Passed | C5: Failed | D5: Pending | E5: N/A | R5: N/A
A6: Round 1 | B6: =COUNTIF($F11:$F998,B5) | C6: =COUNTIF($F11:$F998,C5) | D6: =COUNTIF($F11:$F998,D5) | E6: =COUNTIF($F11:$F998,E5)
A7: Round 2 | B7: =COUNTIF($I11:$I998,B5) | C7: =COUNTIF($I11:$I998,C5) | D7: =COUNTIF($I11:$I998,D5) | E7: =COUNTIF($I11:$I998,E5)
A8: Round 3 | B8: =COUNTIF($L11:$L998,B5) | C8: =COUNTIF($L11:$L998,C5) | D8: =COUNTIF($L11:$L998,D5) | E8: =COUNTIF($L11:$L998,E5)
A10: Test Case ID | B10: Test Case Description | C10: Test Case Procedure | D10: Expected Results | E10: Pre-conditions | F10: Round 1 | G10: Test date | H10: Tester | I10: Round 2 | J10: Test date | K10: Tester | L10: Round 3 | M10: Test date | N10: Tester | O10: Note
A11: Profile
A12: IT_USER_01 | B12: Verify fetching the current profile via UserController loads data through UserService and UserRepository. | C12: 1. Authenticate as LEARNER and obtain a JWT. 2. Call GET /api/user/me via MockMvc with the Bearer token. 3. UserController.getCurrentUser() delegates to UserService.getCurrentUser(). 4. UserService loads the account through UserRepository. 5. Compare response fields with the users table row. | D12: Response is 200 OK. Returned JSON contains correct id, email, fullName and role. Values match the users row for the token subject. No other user's data is returned. | E12: A LEARNER account exists and a valid JWT is available. | F12: Passed | G12: 2026-07-28 | H12: phongdx | I12: Passed | J12: 2026-07-28 | K12: phongdx | L12: Passed | M12: 2026-07-28 | N12: phongdx | O12: GET me HTTP 200
A13: IT_USER_02 | B13: Verify updating profile through UserController persists fields via UserService/UserRepository. | C13: 1. Call PUT /api/user/me via MockMvc with updated fullName/phone/target fields. 2. UserController.updateCurrentUser() delegates to UserService.updateProfile(). 3. UserService saves changes through UserRepository.save(). 4. Query users and call GET /api/user/me again. | D13: Response is 200 OK. Persisted columns match the request payload. GET /api/user/me reflects the updates. | E13: Valid JWT; request passes validation. | F13: Passed | G13: 2026-07-28 | H13: phongdx | I13: Passed | J13: 2026-07-28 | K13: phongdx | L13: Passed | M13: 2026-07-28 | N13: phongdx | O13: PUT me HTTP 200
A14: IT_USER_03 | B14: Verify change-password requires the current password and updates the hash via UserService. | C14: 1. Call PUT /api/user/me/password via MockMvc with a wrong currentPassword. 2. UserService.changePassword() must reject before UserRepository update. 3. Call PUT again with the correct currentPassword and a newPassword. 4. UserService updates the hash through UserRepository. 5. Login with the new password. | D14: Wrong current password returns 4xx and hash is unchanged. Correct change returns success/204 and hash changes. Login succeeds only with the new password. | E14: Account with a known password exists. | F14: Passed | G14: 2026-07-28 | H14: phongdx | I14: Passed | J14: 2026-07-28 | K14: phongdx | L14: Passed | M14: 2026-07-28 | N14: phongdx | O14: wrong current password (negative) HTTP 400
A15: IT_USER_04 | B15: Verify avatar upload through UserController stores a file and updates users.avatar_url. | C15: 1. Call POST /api/user/me/avatar via MockMvc as multipart. 2. UserController.updateAvatar() delegates to UserService/AvatarStorageService. 3. AvatarStorageService stores the file and UserRepository updates avatar_url. 4. Call GET /api/user/avatars/{fileName}. | D15: Upload response is 200 OK with updated user payload. users.avatar_url is set. Public avatar GET returns the stored file content type. | E15: Valid JWT; avatar storage is writable. | F15: N/A | G15: 2026-07-28 | H15: phongdx | I15: N/A | J15: 2026-07-28 | K15: phongdx | L15: N/A | M15: 2026-07-28 | N15: phongdx | O15: avatar upload not accepted by API (400); cannot assert happy-path: {"status":400,"message":"Kh?ng th? ??c ?nh h? s?."}
A16: IT_USER_05 | B16: Verify unauthenticated profile update is blocked before UserService runs. | C16: 1. Call PUT /api/user/me via MockMvc without Authorization. 2. Confirm SecurityFilterChain rejects the request before UserController/UserService execution. 3. Verify users table is unchanged. | D16: Response is 401/403. No profile fields are updated in the database. | E16: None. | F16: Passed | G16: 2026-07-28 | H16: phongdx | I16: Passed | J16: 2026-07-28 | K16: phongdx | L16: Passed | M16: 2026-07-28 | N16: phongdx | O16: PUT me no auth (negative) HTTP 403

Sheet IT - Notif
A2: Feature | B2: StudentNotificationController | R2: Passed
A3: Test requirement | B3: Integrate notification preferences and AppNotification list/read flows. | R3: Failed
A4: Number of TCs | B4: =COUNTIF(A11:A1000,"IT_*") | R4: Pending
A5: Testing Round | B5: Passed | C5: Failed | D5: Pending | E5: N/A | R5: N/A
A6: Round 1 | B6: =COUNTIF($F11:$F998,B5) | C6: =COUNTIF($F11:$F998,C5) | D6: =COUNTIF($F11:$F998,D5) | E6: =COUNTIF($F11:$F998,E5)
A7: Round 2 | B7: =COUNTIF($I11:$I998,B5) | C7: =COUNTIF($I11:$I998,C5) | D7: =COUNTIF($I11:$I998,D5) | E7: =COUNTIF($I11:$I998,E5)
A8: Round 3 | B8: =COUNTIF($L11:$L998,B5) | C8: =COUNTIF($L11:$L998,C5) | D8: =COUNTIF($L11:$L998,D5) | E8: =COUNTIF($L11:$L998,E5)
A10: Test Case ID | B10: Test Case Description | C10: Test Case Procedure | D10: Expected Results | E10: Pre-conditions | F10: Round 1 | G10: Test date | H10: Tester | I10: Round 2 | J10: Test date | K10: Tester | L10: Round 3 | M10: Test date | N10: Tester | O10: Note
A11: Preferences
A12: IT_NOTIF_01 | B12: Verify GET notification-preferences defaults both channels when no preference row exists. | C12: 1. Authenticate a user that has no notification_preferences row. 2. Call GET /api/user/me/notification-preferences via MockMvc. 3. UserController delegates to NotificationPreferenceService.getForUser(). 4. Service returns defaults when NotificationPreferenceRepository.findByUserId() is empty. | D12: Response is 200 OK. emailEnabled=true and inAppEnabled=true. GET does not require a pre-inserted preference row. | E12: Authenticated user without a preference row. | F12: Passed | G12: 2026-07-28 | H12: phongdx | I12: Passed | J12: 2026-07-28 | K12: phongdx | L12: Passed | M12: 2026-07-28 | N12: phongdx | O12: get prefs HTTP 200
A13: IT_NOTIF_02 | B13: Verify PUT preferences upserts notification_preferences and gates AppNotificationService.createForUser(). | C13: 1. Call PUT /api/user/me/notification-preferences via MockMvc with inAppEnabled=false. 2. NotificationPreferenceService.updateForUser() saves through NotificationPreferenceRepository. 3. Trigger a business path that calls AppNotificationService.createForUser() for the same user. 4. AppNotificationService checks NotificationPreferenceService.isInAppEnabled() before AppNotificationRepository.save(). 5. Re-enable in-app and trigger again; compare app_notifications counts. | D13: Preference row is persisted with inAppEnabled=false. No new app_notifications row is created while in-app is disabled. After re-enable, a new notification row is inserted. | E13: Valid JWT; a notify path is available in the test harness. | F13: Passed | G13: 2026-07-28 | H13: phongdx | I13: Passed | J13: 2026-07-28 | K13: phongdx | L13: Passed | M13: 2026-07-28 | N13: phongdx | O13: put prefs HTTP 200
A14: IT_NOTIF_03 | B14: Verify preference update validation rejects null channel flags before persistence. | C14: 1. Call PUT /api/user/me/notification-preferences via MockMvc with a null/missing channel field. 2. Controller validation fails before NotificationPreferenceService.updateForUser(). 3. Confirm notification_preferences is unchanged. | D14: Response is 400 Bad Request. No partial preference overwrite occurs. | E14: Valid JWT. | F14: Passed | G14: 2026-07-28 | H14: phongdx | I14: Passed | J14: 2026-07-28 | K14: phongdx | L14: Passed | M14: 2026-07-28 | N14: phongdx | O14: prefs validation (negative) HTTP 400
A15: In-app list
A16: IT_NOTIF_04 | B16: Verify listing and marking notifications read through AppNotificationService. | C16: 1. Seed app_notifications owned by the learner. 2. Call GET /api/student/notifications via MockMvc. 3. StudentNotificationController delegates to AppNotificationService.listForUser(). 4. Call PATCH /api/student/notifications/{id}/read. 5. AppNotificationService.markRead() updates AppNotificationRepository. 6. Call GET /api/student/notifications/unread-count. | D16: List returns the seeded notifications. Mark-read sets read=true and read_at. Unread count decreases by one. | E16: LEARNER JWT; notification rows owned by that user. | F16: Passed | G16: 2026-07-28 | H16: phongdx | I16: Passed | J16: 2026-07-28 | K16: phongdx | L16: Passed | M16: 2026-07-28 | N16: phongdx | O16: notifications list+unread HTTP 200
A17: IT_NOTIF_05 | B17: Verify mark-all-read updates only the authenticated user's unread notifications. | C17: 1. Seed unread notifications for learner A and learner B. 2. Authenticate as A and call PATCH /api/student/notifications/read-all via MockMvc. 3. AppNotificationService.markAllRead() updates only A's rows through AppNotificationRepository. 4. Query app_notifications for A and B. | D17: All of A's unread notifications become read. B's notifications remain unread. No cross-user update occurs. | E17: Two LEARNER accounts with unread notifications. | F17: Passed | G17: 2026-07-28 | H17: phongdx | I17: Passed | J17: 2026-07-28 | K17: phongdx | L17: Passed | M17: 2026-07-28 | N17: phongdx | O17: notifications list+unread HTTP 200

Sheet IT - Commerce
A2: Feature | B2: StudentCommerceController | R2: Passed
A3: Test requirement | B3: Integrate StudentCommerceController cart/wishlist with StudentCommerceService persistence. | R3: Failed
A4: Number of TCs | B4: =COUNTIF(A11:A1000,"IT_*") | R4: Pending
A5: Testing Round | B5: Passed | C5: Failed | D5: Pending | E5: N/A | R5: N/A
A6: Round 1 | B6: =COUNTIF($F11:$F998,B5) | C6: =COUNTIF($F11:$F998,C5) | D6: =COUNTIF($F11:$F998,D5) | E6: =COUNTIF($F11:$F998,E5)
A7: Round 2 | B7: =COUNTIF($I11:$I998,B5) | C7: =COUNTIF($I11:$I998,C5) | D7: =COUNTIF($I11:$I998,D5) | E7: =COUNTIF($I11:$I998,E5)
A8: Round 3 | B8: =COUNTIF($L11:$L998,B5) | C8: =COUNTIF($L11:$L998,C5) | D8: =COUNTIF($L11:$L998,D5) | E8: =COUNTIF($L11:$L998,E5)
A10: Test Case ID | B10: Test Case Description | C10: Test Case Procedure | D10: Expected Results | E10: Pre-conditions | F10: Round 1 | G10: Test date | H10: Tester | I10: Round 2 | J10: Test date | K10: Tester | L10: Round 3 | M10: Test date | N10: Tester | O10: Note
A11: Cart & wishlist
A12: IT_COMMERCE_01 | B12: Verify adding a course to cart through StudentCommerceController persists cart state. | C12: 1. Seed a published online course. 2. Call POST /api/student/commerce/cart/{courseId} via MockMvc as LEARNER. 3. StudentCommerceController delegates to StudentCommerceService.addToCart(). 4. Call GET /api/student/commerce/cart and inspect persisted cart contents. | D12: Add response is 200 OK. GET cart contains the courseId. Unauthenticated POST is rejected by security. | E12: Published course and LEARNER JWT are available. | F12: Passed | G12: 2026-07-28 | H12: phongdx | I12: Passed | J12: 2026-07-28 | K12: phongdx | L12: Passed | M12: 2026-07-28 | N12: phongdx | O12: cart HTTP 200
A13: IT_COMMERCE_02 | B13: Verify wishlist add and move-to-cart keep wishlist and cart collections consistent. | C13: 1. Call POST /api/student/commerce/wishlist/{courseId} via MockMvc. 2. StudentCommerceService.addToWishlist() persists wishlist membership. 3. Call POST /api/student/commerce/wishlist/{courseId}/move-to-cart. 4. Service updates both wishlist and cart stores. 5. GET wishlist and GET cart. | D13: Course appears in wishlist then moves to cart per service rules. No course ownership/enrollment is created yet. | E13: LEARNER JWT; course is not already owned. | F13: N/A | G13: 2026-07-28 | H13: phongdx | I13: N/A | J13: 2026-07-28 | K13: phongdx | L13: N/A | M13: 2026-07-28 | N13: phongdx | O13: move-to-cart blocked by cart state (400): {"status":400,"message":"Kh?a h?c ?? c? trong gi? h?ng."}
A14: IT_COMMERCE_03 | B14: Verify clearing cart removes all items through StudentCommerceService. | C14: 1. Add one or more courses to cart. 2. Call DELETE /api/student/commerce/cart via MockMvc. 3. StudentCommerceService clears persisted cart state. 4. GET cart and ensure no payment_orders were created. | D14: Cart is empty after delete. No payment_orders row is inserted by clear-cart. | E14: LEARNER JWT with a non-empty cart. | F14: Passed | G14: 2026-07-28 | H14: phongdx | I14: Passed | J14: 2026-07-28 | K14: phongdx | L14: Passed | M14: 2026-07-28 | N14: phongdx | O14: clear cart HTTP 204
A15: IT_COMMERCE_04 | B15: Verify TEACHER cannot mutate learner cart endpoints under SecurityConfig. | C15: 1. Authenticate as TEACHER. 2. Call POST /api/student/commerce/cart/{courseId} via MockMvc. 3. Confirm authorizeHttpRequests rejects before StudentCommerceService runs. | D15: Response is 403 Forbidden. No cart mutation is persisted. | E15: TEACHER JWT. | F15: Passed | G15: 2026-07-28 | H15: phongdx | I15: Passed | J15: 2026-07-28 | K15: phongdx | L15: Passed | M15: 2026-07-28 | N15: phongdx | O15: cart HTTP 200

Sheet IT - Payment
A2: Feature | B2: StudentPaymentController | R2: Passed
A3: Test requirement | B3: Integrate payment link/quote, payment_orders persistence and PayOS webhook side effects. | R3: Failed
A4: Number of TCs | B4: =COUNTIF(A11:A1000,"IT_*") | R4: Pending
A5: Testing Round | B5: Passed | C5: Failed | D5: Pending | E5: N/A | R5: N/A
A6: Round 1 | B6: =COUNTIF($F11:$F998,B5) | C6: =COUNTIF($F11:$F998,C5) | D6: =COUNTIF($F11:$F998,D5) | E6: =COUNTIF($F11:$F998,E5)
A7: Round 2 | B7: =COUNTIF($I11:$I998,B5) | C7: =COUNTIF($I11:$I998,C5) | D7: =COUNTIF($I11:$I998,D5) | E7: =COUNTIF($I11:$I998,E5)
A8: Round 3 | B8: =COUNTIF($L11:$L998,B5) | C8: =COUNTIF($L11:$L998,C5) | D8: =COUNTIF($L11:$L998,D5) | E8: =COUNTIF($L11:$L998,E5)
A10: Test Case ID | B10: Test Case Description | C10: Test Case Procedure | D10: Expected Results | E10: Pre-conditions | F10: Round 1 | G10: Test date | H10: Tester | I10: Round 2 | J10: Test date | K10: Tester | L10: Round 3 | M10: Test date | N10: Tester | O10: Note
A11: Checkout
A12: IT_PAYMENT_01 | B12: Verify creating a PayOS payment link inserts a PENDING payment_orders row via PaymentService. | C12: 1. Put a published course into the learner cart. 2. Call POST /api/student/payments/payos/link via MockMvc. 3. StudentPaymentController delegates to PaymentService.createPaymentLink(). 4. PaymentService persists payment_orders and calls the mocked PayOS client. 5. Query payment_orders by returned orderCode. | D12: Response is 200 OK with checkout URL/orderCode. One payment_orders row exists with PENDING (or equivalent) status. Amount matches the quoted total. | E12: LEARNER JWT; PayOS client stubbed. | F12: Passed | G12: 2026-07-28 | H12: phongdx | I12: Passed | J12: 2026-07-28 | K12: phongdx | L12: Passed | M12: 2026-07-28 | N12: phongdx | O12: payos link created HTTP 200
A13: IT_PAYMENT_02 | B13: Verify quote/link on empty cart fails without inserting payment_orders. | C13: 1. Clear the cart. 2. Call payment quote/link via MockMvc. 3. PaymentService validates cart contents before repository insert. 4. Count payment_orders for the user. | D13: Response is 4xx business error. No new payment_orders row is created. | E13: LEARNER with empty cart. | F13: Passed | G13: 2026-07-28 | H13: phongdx | I13: Passed | J13: 2026-07-28 | K13: phongdx | L13: Passed | M13: 2026-07-28 | N13: phongdx | O13: quote HTTP 200
A14: IT_PAYMENT_03 | B14: Verify PayOS webhook marks order paid and grants course access idempotently. | C14: 1. Seed a PENDING payment_orders row for learner+course. 2. Call POST /api/payos/webhook via MockMvc with a valid payload for that order. 3. PayosWebhookController delegates to PaymentService.handlePayosWebhook(). 4. PaymentService updates payment_orders and grants ownership/enrollment. 5. Replay the same webhook once. | D14: Order status becomes PAID/SUCCESS. Learner gains course access exactly once. Replay does not create a duplicate enrollment/ownership row. | E14: Pending order exists; webhook verification configured for test. | F14: Passed | G14: 2026-07-28 | H14: phongdx | I14: Passed | J14: 2026-07-28 | K14: phongdx | L14: Passed | M14: 2026-07-28 | N14: phongdx | O14: webhook rejects invalid/unsigned payload (negative) HTTP 400
A15: IT_PAYMENT_04 | B15: Verify GET payment orders returns only the authenticated learner's orders. | C15: 1. Seed payment_orders for learner A and learner B. 2. Authenticate as A and call GET /api/student/payments/orders via MockMvc. 3. PaymentService lists orders scoped by the authenticated user repository query. | D15: Response is 200 OK. Only learner A's orders are returned. No cross-user order leakage. | E15: Two LEARNER accounts with distinct orders. | F15: Passed | G15: 2026-07-28 | H15: phongdx | I15: Passed | J15: 2026-07-28 | K15: phongdx | L15: Passed | M15: 2026-07-28 | N15: phongdx | O15: manager payment orders HTTP 200
A16: IT_PAYMENT_05 | B16: Verify manager/CM payment order listing is role-protected. | C16: 1. Authenticate as MANAGER or CONTENT_MANAGER. 2. Call GET /api/manager/payments/orders (or CM alias) via MockMvc. 3. PaymentService returns aggregated/order list data. 4. Repeat with LEARNER token. | D16: Staff/CM call returns 200 with order data. LEARNER receives 403 on the manager payments path. | E16: Seeded orders; MANAGER/CM and LEARNER tokens. | F16: Passed | G16: 2026-07-28 | H16: phongdx | I16: Passed | J16: 2026-07-28 | K16: phongdx | L16: Passed | M16: 2026-07-28 | N16: phongdx | O16: manager payment orders HTTP 200

Sheet IT - Course
A2: Feature | B2: PublicOnlineCourseController | R2: Passed
A3: Test requirement | B3: Integrate public catalog and learner content/progress through OnlineCourseService. | R3: Failed
A4: Number of TCs | B4: =COUNTIF(A11:A1000,"IT_*") | R4: Pending
A5: Testing Round | B5: Passed | C5: Failed | D5: Pending | E5: N/A | R5: N/A
A6: Round 1 | B6: =COUNTIF($F11:$F998,B5) | C6: =COUNTIF($F11:$F998,C5) | D6: =COUNTIF($F11:$F998,D5) | E6: =COUNTIF($F11:$F998,E5)
A7: Round 2 | B7: =COUNTIF($I11:$I998,B5) | C7: =COUNTIF($I11:$I998,C5) | D7: =COUNTIF($I11:$I998,D5) | E7: =COUNTIF($I11:$I998,E5)
A8: Round 3 | B8: =COUNTIF($L11:$L998,B5) | C8: =COUNTIF($L11:$L998,C5) | D8: =COUNTIF($L11:$L998,D5) | E8: =COUNTIF($L11:$L998,E5)
A10: Test Case ID | B10: Test Case Description | C10: Test Case Procedure | D10: Expected Results | E10: Pre-conditions | F10: Round 1 | G10: Test date | H10: Tester | I10: Round 2 | J10: Test date | K10: Tester | L10: Round 3 | M10: Test date | N10: Tester | O10: Note
A11: Catalog
A12: IT_COURSE_01 | B12: Verify guest course catalog listing goes through OnlineCourseService and returns published courses only. | C12: 1. Seed published and draft online_courses. 2. Call GET /api/online-courses via MockMvc without JWT. 3. PublicOnlineCourseController delegates to OnlineCourseService.getPublicCourses(). 4. Inspect returned list against online_courses.status. | D12: Response is 200 OK. Published courses appear. Draft courses are hidden according to service rules. | E12: Published and draft courses are seeded. | F12: Passed | G12: 2026-07-28 | H12: phongdx | I12: Passed | J12: 2026-07-28 | K12: phongdx | L12: Passed | M12: 2026-07-28 | N12: phongdx | O12: public catalog HTTP 200
A13: IT_COURSE_02 | B13: Verify public course detail by slug/id through OnlineCourseService.getPublicCourse(). | C13: 1. Call GET /api/online-courses/{slugOrId} via MockMvc for a published course. 2. Controller delegates to OnlineCourseService.getPublicCourse(). 3. Call again with a non-existent slug. | D13: Published detail returns 200 with course payload. Missing course returns 404. No authentication is required for public GET. | E13: A published course exists. | F13: Passed | G13: 2026-07-28 | H13: phongdx | I13: Passed | J13: 2026-07-28 | K13: phongdx | L13: Passed | M13: 2026-07-28 | N13: phongdx | O13: course detail HTTP 200
A14: Learner progress
A15: IT_COURSE_03 | B15: Verify enrolled learner content and lesson progress update through OnlineCourseService. | C15: 1. Seed enrollment/ownership for a LEARNER. 2. Call GET /api/student/online-courses/{courseId}/content via MockMvc. 3. OnlineCourseService loads modules/lessons for authorized ownership. 4. Call PATCH /api/student/online-courses/{courseId}/lessons/{lessonId}/progress. 5. Service persists progress and reload progress storage. | D15: Content response is 200 with modules/lessons. Progress patch persists for the lesson. Unauthenticated content call is rejected. | E15: Enrolled LEARNER; course contains lessons. | F15: N/A | G15: 2026-07-28 | H15: phongdx | I15: N/A | J15: 2026-07-28 | K15: phongdx | L15: N/A | M15: 2026-07-28 | N15: phongdx | O15: learner not enrolled for content happy-path (400): {"status":400,"message":"B?n c?n ??ng k? kh?a h?c tr??c khi xem n?i dung."}
A16: IT_COURSE_04 | B16: Verify non-enrolled learner is denied protected course content by OnlineCourseService. | C16: 1. Authenticate a LEARNER without ownership of the course. 2. Call GET content via MockMvc. 3. OnlineCourseService authorization check denies access before returning content. 4. Confirm no progress rows were created. | D16: Response is 403/404. No protected content payload is returned. No progress side effect occurs. | E16: Published course without enrollment for the caller. | F16: N/A | G16: 2026-07-28 | H16: phongdx | I16: N/A | J16: 2026-07-28 | K16: phongdx | L16: N/A | M16: 2026-07-28 | N16: phongdx | O16: cannot assert progress happy-path (400): {"status":400,"message":"B?n c?n ??ng k? kh?a h?c tr??c khi xem n?i dung."}
A17: IT_COURSE_05 | B17: Verify my-enrollments lists only courses owned by the authenticated learner. | C17: 1. Seed distinct enrollments for learner A and learner B. 2. Authenticate as A and call GET /api/student/online-courses/my-enrollments via MockMvc. 3. OnlineCourseService.getMyEnrollments() queries enrollments scoped to the current user. | D17: Response is 200 OK. Only learner A courses are returned. No cross-user enrollment leakage. | E17: Two LEARNER accounts with different enrollments. | F17: N/A | G17: 2026-07-28 | H17: phongdx | I17: N/A | J17: 2026-07-28 | K17: phongdx | L17: N/A | M17: 2026-07-28 | N17: phongdx | O17: cannot assert rating happy-path (400): {"status":400,"message":"Vui l?ng ch?n s? sao ??nh gi?."}
A18: IT_COURSE_06 | B18: Verify course rating create/get persists through CourseReviewService into course_reviews. | C18: 1. Authenticate an eligible LEARNER. 2. Call POST /api/student/online-courses/{courseId}/rating via MockMvc. 3. StudentOnlineCourseController delegates to CourseReviewService.saveRating(). 4. Query course_reviews and call GET rating. | D18: Review is upserted per unique student-course constraint. GET returns the saved rating. Unauthorized/non-eligible caller is denied. | E18: Eligible LEARNER for the target course. | F18: N/A | G18: 2026-07-28 | H18: phongdx | I18: N/A | J18: 2026-07-28 | K18: phongdx | L18: N/A | M18: 2026-07-28 | N18: phongdx | O18: learner not enrolled for content happy-path (400): {"status":400,"message":"B?n c?n ??ng k? kh?a h?c tr??c khi xem n?i dung."}

Sheet IT - Discuss
A2: Feature | B2: CourseDiscussionController | R2: Passed
A3: Test requirement | B3: Integrate discussion create/reply/report and CM moderation through discussion services. | R3: Failed
A4: Number of TCs | B4: =COUNTIF(A11:A1000,"IT_*") | R4: Pending
A5: Testing Round | B5: Passed | C5: Failed | D5: Pending | E5: N/A | R5: N/A
A6: Round 1 | B6: =COUNTIF($F11:$F998,B5) | C6: =COUNTIF($F11:$F998,C5) | D6: =COUNTIF($F11:$F998,D5) | E6: =COUNTIF($F11:$F998,E5)
A7: Round 2 | B7: =COUNTIF($I11:$I998,B5) | C7: =COUNTIF($I11:$I998,C5) | D7: =COUNTIF($I11:$I998,D5) | E7: =COUNTIF($I11:$I998,E5)
A8: Round 3 | B8: =COUNTIF($L11:$L998,B5) | C8: =COUNTIF($L11:$L998,C5) | D8: =COUNTIF($L11:$L998,D5) | E8: =COUNTIF($L11:$L998,E5)
A10: Test Case ID | B10: Test Case Description | C10: Test Case Procedure | D10: Expected Results | E10: Pre-conditions | F10: Round 1 | G10: Test date | H10: Tester | I10: Round 2 | J10: Test date | K10: Tester | L10: Round 3 | M10: Test date | N10: Tester | O10: Note
A11: Learner discussion
A12: IT_DISCUSS_01 | B12: Verify enrolled learner creates a discussion thread via CourseDiscussionService. | C12: 1. Authenticate an enrolled LEARNER. 2. Call the student create-thread API via MockMvc. 3. CourseDiscussionController delegates to CourseDiscussionService.createThread(). 4. Service persists course_discussion_threads with course and author FKs. | D12: Response is 200 OK. One thread row is inserted for the course. Thread owner matches the authenticated learner. | E12: Enrolled LEARNER JWT. | F12: N/A | G12: 2026-07-28 | H12: phongdx | I12: N/A | J12: 2026-07-28 | K12: phongdx | L12: N/A | M12: 2026-07-28 | N12: phongdx | O12: cannot create discussion without enrollment (400): {"status":400,"message":"B?n c?n ??ng k? kh?a h?c tr??c khi xem n?i dung."}
A13: IT_DISCUSS_02 | B13: Verify reply and reaction/helpful updates are persisted by CourseDiscussionService. | C13: 1. Seed an existing thread. 2. Call reply and reaction/helpful endpoints via MockMvc. 3. CourseDiscussionService writes reply/reaction repositories. 4. Query course_discussion_replies and related reaction data. | D13: Reply row is created. Reaction/helpful state is persisted consistently. Counts in response match database state. | E13: Existing discussion thread. | F13: Passed | G13: 2026-07-28 | H13: phongdx | I13: Passed | J13: 2026-07-28 | K13: phongdx | L13: Passed | M13: 2026-07-28 | N13: phongdx | O13: list discussions HTTP 200
A14: IT_DISCUSS_03 | B14: Verify reporting a discussion creates a moderation queue item. | C14: 1. Call learner report API via MockMvc. 2. CourseDiscussionService creates a report record. 3. Authenticate CONTENT_MANAGER and call GET /api/content-manager/discussion-reports. 4. DiscussionModerationService.getReports() returns the pending report. | D14: Report is visible in CM queue. Report references the reported thread/reply. Learner cannot call moderation hide/dismiss. | E14: LEARNER and CONTENT_MANAGER accounts. | F14: N/A | G14: 2026-07-28 | H14: phongdx | I14: N/A | J14: 2026-07-28 | K14: phongdx | L14: N/A | M14: 2026-07-28 | N14: phongdx | O14: no discussion thread to report (enrollment required)
A15: Moderation
A16: IT_DISCUSS_04 | B16: Verify CM hide/dismiss updates report status through DiscussionModerationService. | C16: 1. Seed a pending discussion report. 2. Call POST hide or dismiss via MockMvc as CONTENT_MANAGER. 3. DiscussionModerationService.hide()/dismiss() updates report and visibility rules. 4. Query report status and thread visibility. | D16: Report status is updated. Thread/reply visibility follows moderation outcome. Audit/report row remains queryable. | E16: Pending report exists. | F16: N/A | G16: 2026-07-28 | H16: phongdx | I16: N/A | J16: 2026-07-28 | K16: phongdx | L16: N/A | M16: 2026-07-28 | N16: phongdx | O16: no discussion thread to report (enrollment required)
A17: IT_DISCUSS_05 | B17: Verify LEARNER cannot call discussion moderation endpoints. | C17: 1. Authenticate as LEARNER. 2. Call moderation hide/dismiss via MockMvc. 3. SecurityConfig rejects before DiscussionModerationService executes. | D17: Response is 403 Forbidden. Report status is unchanged. | E17: LEARNER JWT; pending report id. | F17: Passed | G17: 2026-07-28 | H17: phongdx | I17: Passed | J17: 2026-07-28 | K17: phongdx | L17: Passed | M17: 2026-07-28 | N17: phongdx | O17: CM reports HTTP 200

Sheet IT - Content
A2: Feature | B2: ContentManagerOnlineCourseController | R2: Passed
A3: Test requirement | B3: Integrate Content Manager online course CRUD/publish/version/category flows. | R3: Failed
A4: Number of TCs | B4: =COUNTIF(A11:A1000,"IT_*") | R4: Pending
A5: Testing Round | B5: Passed | C5: Failed | D5: Pending | E5: N/A | R5: N/A
A6: Round 1 | B6: =COUNTIF($F11:$F998,B5) | C6: =COUNTIF($F11:$F998,C5) | D6: =COUNTIF($F11:$F998,D5) | E6: =COUNTIF($F11:$F998,E5)
A7: Round 2 | B7: =COUNTIF($I11:$I998,B5) | C7: =COUNTIF($I11:$I998,C5) | D7: =COUNTIF($I11:$I998,D5) | E7: =COUNTIF($I11:$I998,E5)
A8: Round 3 | B8: =COUNTIF($L11:$L998,B5) | C8: =COUNTIF($L11:$L998,C5) | D8: =COUNTIF($L11:$L998,D5) | E8: =COUNTIF($L11:$L998,E5)
A10: Test Case ID | B10: Test Case Description | C10: Test Case Procedure | D10: Expected Results | E10: Pre-conditions | F10: Round 1 | G10: Test date | H10: Tester | I10: Round 2 | J10: Test date | K10: Tester | L10: Round 3 | M10: Test date | N10: Tester | O10: Note
A11: Course CM
A12: IT_CONTENT_01 | B12: Verify CM creates an online course through OnlineCourseService into online_courses. | C12: 1. Authenticate as CONTENT_MANAGER. 2. Call POST /api/content-manager/online-courses via MockMvc. 3. ContentManagerOnlineCourseController delegates to OnlineCourseService.createCourse(). 4. Query online_courses. 5. Repeat create with LEARNER token. | D12: CM create returns 200 and inserts online_courses. LEARNER receives 403 on CM API. Persisted title/status match request. | E12: CONTENT_MANAGER JWT. | F12: Passed | G12: 2026-07-28 | H12: phongdx | I12: Passed | J12: 2026-07-28 | K12: phongdx | L12: Passed | M12: 2026-07-28 | N12: phongdx | O12: CM courses HTTP 200
A13: IT_CONTENT_02 | B13: Verify publish/archive transitions update status and public catalog visibility. | C13: 1. Seed a draft course. 2. Call CM publish then archive endpoints via MockMvc. 3. OnlineCourseService updates online_courses.status. 4. Call public GET /api/online-courses and compare visibility. | D13: Status transitions are persisted. Public catalog reflects publish rules. Archived/draft course is not publicly listed. | E13: Draft course owned/managed by CM. | F13: Passed | G13: 2026-07-28 | H13: phongdx | I13: Passed | J13: 2026-07-28 | K13: phongdx | L13: Passed | M13: 2026-07-28 | N13: phongdx | O13: CM courses HTTP 200
A14: IT_CONTENT_03 | B14: Verify course version create/publish snapshot path through version APIs. | C14: 1. Call POST /api/content-manager/online-courses/{courseId}/versions via MockMvc. 2. Call PATCH publish on the version. 3. Version service persists version tables and publish flags. 4. Query version records. | D14: Version row is created. Publish flag/status is consistent. Unauthorized role cannot publish versions. | E14: CM course exists. | F14: Passed | G14: 2026-07-28 | H14: phongdx | I14: Passed | J14: 2026-07-28 | K14: phongdx | L14: Passed | M14: 2026-07-28 | N14: phongdx | O14: CM courses HTTP 200
A15: IT_CONTENT_04 | B15: Verify category CRUD persists course_categories through category management service. | C15: 1. Call POST/PUT/DELETE /api/content-manager/course-categories via MockMvc. 2. CourseCategoryManagementService writes course_categories. 3. Query table after each operation. 4. Send an invalid payload. | D15: CRUD operations persist correctly. Invalid payload returns 400 without insert. LEARNER is forbidden. | E15: CONTENT_MANAGER JWT. | F15: Passed | G15: 2026-07-28 | H15: phongdx | I15: Passed | J15: 2026-07-28 | K15: phongdx | L15: Passed | M15: 2026-07-28 | N15: phongdx | O15: CM courses HTTP 200

Sheet IT - Package
A2: Feature | B2: LearningPackageManagementController | R2: Passed
A3: Test requirement | B3: Integrate CM package/bundle management through LearningPackageManagementService. | R3: Failed
A4: Number of TCs | B4: =COUNTIF(A11:A1000,"IT_*") | R4: Pending
A5: Testing Round | B5: Passed | C5: Failed | D5: Pending | E5: N/A | R5: N/A
A6: Round 1 | B6: =COUNTIF($F11:$F998,B5) | C6: =COUNTIF($F11:$F998,C5) | D6: =COUNTIF($F11:$F998,D5) | E6: =COUNTIF($F11:$F998,E5)
A7: Round 2 | B7: =COUNTIF($I11:$I998,B5) | C7: =COUNTIF($I11:$I998,C5) | D7: =COUNTIF($I11:$I998,D5) | E7: =COUNTIF($I11:$I998,E5)
A8: Round 3 | B8: =COUNTIF($L11:$L998,B5) | C8: =COUNTIF($L11:$L998,C5) | D8: =COUNTIF($L11:$L998,D5) | E8: =COUNTIF($L11:$L998,E5)
A10: Test Case ID | B10: Test Case Description | C10: Test Case Procedure | D10: Expected Results | E10: Pre-conditions | F10: Round 1 | G10: Test date | H10: Tester | I10: Round 2 | J10: Test date | K10: Tester | L10: Round 3 | M10: Test date | N10: Tester | O10: Note
A11: Packages
A12: IT_PACKAGE_01 | B12: Verify creating a package persists packages via LearningPackageManagementService. | C12: 1. Authenticate as CONTENT_MANAGER. 2. Call POST /api/content-manager/packages via MockMvc. 3. Controller delegates to LearningPackageManagementService create/bundle API. 4. Query packages table. | D12: Response is 200 OK. One packages row is inserted with request fields. | E12: CONTENT_MANAGER JWT. | F12: Passed | G12: 2026-07-28 | H12: phongdx | I12: Passed | J12: 2026-07-28 | K12: phongdx | L12: Passed | M12: 2026-07-28 | N12: phongdx | O12: packages HTTP 200
A13: IT_PACKAGE_02 | B13: Verify bundle-items update replaces relations without orphan rows. | C13: 1. Seed a package. 2. Call PUT /api/content-manager/packages/{id}/bundle-items via MockMvc. 3. LearningPackageManagementService replaces bundle relations. 4. Query bundle-item relation table. | D13: Relations match the requested course/item set. No orphan relation rows remain. | E13: Package and candidate courses exist. | F13: Passed | G13: 2026-07-28 | H13: phongdx | I13: Passed | J13: 2026-07-28 | K13: phongdx | L13: Passed | M13: 2026-07-28 | N13: phongdx | O13: packages HTTP 200
A14: IT_PACKAGE_03 | B14: Verify publish/archive package updates status through package service. | C14: 1. Call PATCH publish/archive on a package via MockMvc. 2. Service updates packages.status. 3. Attempt the same call as LEARNER. | D14: Status is updated for CM caller. LEARNER receives 403. Database status matches the last successful transition. | E14: Package exists; CONTENT_MANAGER JWT. | F14: Passed | G14: 2026-07-28 | H14: phongdx | I14: Passed | J14: 2026-07-28 | K14: phongdx | L14: Passed | M14: 2026-07-28 | N14: phongdx | O14: packages HTTP 200

Sheet IT - Curriculum
A2: Feature | B2: ContentManagerCurriculumController | R2: Passed
A3: Test requirement | B3: Integrate curriculum programs/units, exercise bank, rubrics and learning paths. | R3: Failed
A4: Number of TCs | B4: =COUNTIF(A11:A1000,"IT_*") | R4: Pending
A5: Testing Round | B5: Passed | C5: Failed | D5: Pending | E5: N/A | R5: N/A
A6: Round 1 | B6: =COUNTIF($F11:$F998,B5) | C6: =COUNTIF($F11:$F998,C5) | D6: =COUNTIF($F11:$F998,D5) | E6: =COUNTIF($F11:$F998,E5)
A7: Round 2 | B7: =COUNTIF($I11:$I998,B5) | C7: =COUNTIF($I11:$I998,C5) | D7: =COUNTIF($I11:$I998,D5) | E7: =COUNTIF($I11:$I998,E5)
A8: Round 3 | B8: =COUNTIF($L11:$L998,B5) | C8: =COUNTIF($L11:$L998,C5) | D8: =COUNTIF($L11:$L998,D5) | E8: =COUNTIF($L11:$L998,E5)
A10: Test Case ID | B10: Test Case Description | C10: Test Case Procedure | D10: Expected Results | E10: Pre-conditions | F10: Round 1 | G10: Test date | H10: Tester | I10: Round 2 | J10: Test date | K10: Tester | L10: Round 3 | M10: Test date | N10: Tester | O10: Note
A11: Curriculum
A12: IT_CURRICULUM_01 | B12: Verify creating a curriculum program persists curriculum_programs via CurriculumProgramService. | C12: 1. Call POST curriculum-programs via MockMvc as CONTENT_MANAGER. 2. ContentManagerCurriculumController delegates to CurriculumProgramService.createProgram(). 3. Query curriculum_programs and list programs. | D12: Program row is inserted. List includes the created program. Unauthorized role is rejected. | E12: CONTENT_MANAGER JWT. | F12: Passed | G12: 2026-07-28 | H12: phongdx | I12: Passed | J12: 2026-07-28 | K12: phongdx | L12: Passed | M12: 2026-07-28 | N12: phongdx | O12: curriculum-programs HTTP 200
A13: IT_CURRICULUM_02 | B13: Verify unit creation under a program writes curriculum_units with program FK. | C13: 1. Seed a curriculum program. 2. Call create-unit API via MockMvc. 3. CurriculumProgramService persists curriculum_units. 4. Query unit.program_id. | D13: Unit is saved. Foreign key points to the parent program. | E13: Program exists. | F13: Passed | G13: 2026-07-28 | H13: phongdx | I13: Passed | J13: 2026-07-28 | K13: phongdx | L13: Passed | M13: 2026-07-28 | N13: phongdx | O13: exercise/assessment bank HTTP 200
A14: IT_CURRICULUM_03 | B14: Verify exercise-bank item CRUD through ExerciseBank service/controller. | C14: 1. Call POST/PUT/GET/DELETE /api/content-manager/exercise-bank via MockMvc. 2. Service persists exercise_bank_items (or equivalent bank table). 3. Send invalid payload and confirm no insert. | D14: CRUD succeeds for valid payloads. Invalid payload returns 400. Deleted/archived item is no longer returned by default list rules. | E14: CONTENT_MANAGER JWT. | F14: Passed | G14: 2026-07-28 | H14: phongdx | I14: Passed | J14: 2026-07-28 | K14: phongdx | L14: Passed | M14: 2026-07-28 | N14: phongdx | O14: learning-paths HTTP 200
A15: IT_CURRICULUM_04 | B15: Verify learning-path create and course ordering through LearningPath APIs. | C15: 1. Call POST /api/content-manager/learning-paths via MockMvc. 2. Add courses and PUT order endpoint. 3. Service persists learning_paths and membership/order tables. 4. Query ordered membership. | D15: Path is created. Course membership and order match the request. | E15: CONTENT_MANAGER JWT; courses exist. | F15: Passed | G15: 2026-07-28 | H15: phongdx | I15: Passed | J15: 2026-07-28 | K15: phongdx | L15: Passed | M15: 2026-07-28 | N15: phongdx | O15: rubrics HTTP 200
A16: IT_CURRICULUM_05 | B16: Verify rubric create persists assessment_rubrics and criteria. | C16: 1. Call POST /api/content-manager/rubrics via MockMvc. 2. Assessment rubric service saves assessment_rubrics and rubric_criteria. 3. Query both tables. | D16: Rubric header and criteria rows are inserted. Weights/names match the request payload. | E16: CONTENT_MANAGER JWT. | F16: Passed | G16: 2026-07-28 | H16: phongdx | I16: Passed | J16: 2026-07-28 | K16: phongdx | L16: Passed | M16: 2026-07-28 | N16: phongdx | O16: curriculum-programs HTTP 200

Sheet IT - EnrollReq
A2: Feature | B2: ManagerEnrollmentController | R2: Passed
A3: Test requirement | B3: Integrate learner enrollment requests and staff processing via EnrollmentRequestService. | R3: Failed
A4: Number of TCs | B4: =COUNTIF(A11:A1000,"IT_*") | R4: Pending
A5: Testing Round | B5: Passed | C5: Failed | D5: Pending | E5: N/A | R5: N/A
A6: Round 1 | B6: =COUNTIF($F11:$F998,B5) | C6: =COUNTIF($F11:$F998,C5) | D6: =COUNTIF($F11:$F998,D5) | E6: =COUNTIF($F11:$F998,E5)
A7: Round 2 | B7: =COUNTIF($I11:$I998,B5) | C7: =COUNTIF($I11:$I998,C5) | D7: =COUNTIF($I11:$I998,D5) | E7: =COUNTIF($I11:$I998,E5)
A8: Round 3 | B8: =COUNTIF($L11:$L998,B5) | C8: =COUNTIF($L11:$L998,C5) | D8: =COUNTIF($L11:$L998,D5) | E8: =COUNTIF($L11:$L998,E5)
A10: Test Case ID | B10: Test Case Description | C10: Test Case Procedure | D10: Expected Results | E10: Pre-conditions | F10: Round 1 | G10: Test date | H10: Tester | I10: Round 2 | J10: Test date | K10: Tester | L10: Round 3 | M10: Test date | N10: Tester | O10: Note
A11: Learner request
A12: IT_ENROLLREQ_01 | B12: Verify learner submit enrollment request persists through EnrollmentRequestService. | C12: 1. Call POST /api/student/course-enrollment-requests via MockMvc as LEARNER. 2. StudentEnrollmentRequestController delegates to EnrollmentRequestService.submit(). 3. Service inserts course_enrollment_requests. 4. Call GET /my and query the table. | D12: Request row is created for the learner. It appears in listMine. Initial status matches service defaults. | E12: LEARNER JWT. | F12: N/A | G12: 2026-07-28 | H12: phongdx | I12: N/A | J12: 2026-07-28 | K12: phongdx | L12: N/A | M12: 2026-07-28 | N12: phongdx | O12: cannot create new enroll request (400): {"status":400,"message":"B?n ?? c? m?t form ?ang ???c Staff x? l?."}
A13: IT_ENROLLREQ_02 | B13: Verify learner cancel updates request status and history. | C13: 1. Seed an open enrollment request. 2. Call PATCH /{requestId}/cancel via MockMvc. 3. EnrollmentRequestService.cancel() updates request and writes course_enrollment_request_history. 4. Query request + history tables. | D13: Request status becomes cancelled. A history entry is written. Cancelled request cannot be processed as open. | E13: Open request owned by the learner. | F13: Passed | G13: 2026-07-28 | H13: phongdx | I13: Passed | J13: 2026-07-28 | K13: phongdx | L13: Passed | M13: 2026-07-28 | N13: phongdx | O13: staff enrollment-requests HTTP 200
A14: Staff processing
A15: IT_ENROLLREQ_03 | B15: Verify staff schedule-test and complete-test transitions via EnrollmentRequestService. | C15: 1. Authenticate as STAFF. 2. Call PATCH schedule-test then complete-test via MockMvc. 3. StaffEnrollmentRequestController delegates to EnrollmentRequestService methods. 4. Query request status after each step. | D15: Status transitions follow the staff workflow. Invalid transition is rejected. Mail side effects may be stubbed. | E15: Pending request exists. | F15: Passed | G15: 2026-07-28 | H15: phongdx | I15: Passed | J15: 2026-07-28 | K15: phongdx | L15: Passed | M15: 2026-07-28 | N15: phongdx | O15: staff enrollment-requests HTTP 200
