Workbook
Name ACTION: #REF!
Name ACTION: #REF!

Sheet Cover
A2: TÀI LIỆU BÁO CÁO KIỂM THỬ | B2: TÀI LIỆU BÁO CÁO KIỂM THỬ
A4: Tên dự án | B4: phòng thí nghiệm tiếng anh | E4: Người tạo | F4: phongdx
A5: Mã dự án | B5: SEP490_G23 | E5: Ngày ban hành | F5: 2026-08-06
A6: Mã tài liệu | B6: =B5&"_"&"XXX"&"_"&"vx.x" | E6: Phiên bản | F6: mẫu v6.0-IT
A9: Lịch sử thay đổi
A10: Ngày hiệu lực | B10: Phiên bản | C10: Hạng mục thay đổi | D10: *A,D,M | E10: Mô tả thay đổi | F10: Tham chiếu
A11: 2026-08-06 | B11: mẫu v6.0-IT | C11: Viết lại tất cả các trường hợp IT theo kiểu mẫu Controller–Service–Repository (MockMvc, không có giao diện người dùng) | D11: M | E11: Tên hàm = Tiêu đề ca sử dụng SRS. Tên trang tính = Tiền tố ID ca kiểm thử (ví dụ: IT_COURSE cho IT_COURSE_01). Quy trình = Gọi API qua MockMvc; Kiểm soát viên đại diện cho Dịch vụ; Dịch vụ sử dụng Kho lưu trữ. Dự kiến ​​= trạng thái HTTP và kiểm tra JSON/DB. Vòng 1 = Đang chờ xử lý. | F11: Các trường hợp sử dụng Báo cáo SRS3 (UC-01..UC-51); hình thức IT hiện có
E12: Đã thực hiện 3 vòng (cố định API CLASS/ASNTEACH/BROADCAST/GMEET) vào ngày 07/08/2026 với http://localhost:8080; người kiểm tra=phongdx; trạng thái/ngày/người kiểm tra được điền mà không tạo lại bố cục trang tính.
A13: Ngôn ngữ | B13: Tiếng Việt — dịch dễ đọc từ COMPLETED.xlsx; giữ nguyên Test Case ID, đường API, mã HTTP, ngày test / tester.

Sheet Test Cases
D1: DANH SÁCH TEST CASE
B3: Tên dự án | D3: =Cover!B4
B4: Mã dự án | D4: =Cover!B5
B5: Mô tả môi trường kiểm thử | D5: 1. Máy chủ: Spring Boot 4 + JDK 21 (@SpringBootTest + MockMvc) 2. Cơ sở dữ liệu: PostgreSQL có áp dụng di chuyển 3. Trình duyệt web: N/A để kiểm tra tích hợp API (Người đưa thư/curl tùy chọn) 4. JWT đã bật bảo mật; hạt giống vai trò 5. Bên ngoài PayOS / Thư / Song Tử / Gặp gỡ sơ khai hoặc hộp cát 6. Tên tính năng được ánh xạ tới các Trường hợp sử dụng Báo cáo SRS3 (tiêu đề UC-xx, không có hậu tố Controller)
B8: STT | C8: Tên chức năng | D8: Tên trang tính | E8: Sự miêu tả | F8: Điều kiện trước
B9: 1 | C9: Xem khóa học công khai | D9: IT_COURSE | E9: IT cho duyệt/tìm kiếm/chi tiết danh mục khóa học công cộng (Controller–Service–Repository). Trường hợp sử dụng: UC-02 Xem các khóa học công khai. Thành phần: PublicOnlineCourseController, OnlineCourseService, OnlineCourseRepository. Các trường hợp thử nghiệm trong trang tính: 5. | F9: DB lên; hạt giống vai trò; bảng mục tiêu `IT_COURSE` tồn tại; các hệ thống bên ngoài được khai báo khi cần thiết cho mô-đun này.
B10: 2 | C10: Truy cập tài liệu học online | D10: IT_ACCESS | E10: IT cho nội dung và tiến trình khóa học của người học đã đăng ký (Controller–Service–Repository). Các trường hợp sử dụng: UC-48 Truy cập Tài liệu Học tập Trực tuyến. Thành phần: StudentOnlineCourseController, OnlineCourseService, OnlineCourseRepository. Các trường hợp thử nghiệm trong bảng: 2. | F10: DB lên; hạt giống vai trò; bảng mục tiêu `IT_ACCESS` tồn tại; các hệ thống bên ngoài được khai báo khi cần thiết cho mô-đun này.
B11: 3 | C11: Xếp học viên vào lớp | D11: IT_ASSIGN | E11: IT cho hàng đợi yêu cầu đăng ký nhân viên và phân công lớp học (Controller-Service-Repository). Các trường hợp sử dụng: UC-38 Chỉ định Người học vào Lớp học. Thành phần: StaffEnrollmentRequestController, EnrollmentRequestService, EnrollmentRequestRepository. Các trường hợp kiểm thử trong sheet: 4. | F11: DB lên; hạt giống vai trò; bảng mục tiêu `IT_ASSIGN` tồn tại; các hệ thống bên ngoài được khai báo khi cần thiết cho mô-đun này.
B12: 4 | C12: Đăng ký khóa học | D12: IT_ENROLL | E12: IT cho yêu cầu đăng ký của người học và đăng ký của tôi (Controller–Service–Repository). Trường hợp sử dụng: UC-08 Đăng ký khóa học. Thành phần: StudentEnrollmentRequestController, StudentOnlineCourseController, EnrollmentRequestService, OnlineCourseService, EnrollmentRequestRepository. Các trường hợp thử nghiệm trong bảng: 2. | F12: DB lên; hạt giống vai trò; bảng mục tiêu `IT_ENROLL` tồn tại; các hệ thống bên ngoài được khai báo khi cần thiết cho mô-đun này.
B13: 5 | C13: Danh sách yêu thích khóa học | D13: IT_WISHLIST | E13: IT cho duy trì danh sách mong muốn (Controller–Service–Repository). Trường hợp sử dụng: Các khóa học trong danh sách mong muốn của UC-45. Thành phần: StudentCommerceController, StudentCommerceService, WishlistItemRepository. Các trường hợp thử nghiệm trong bảng: 2. | F13: DB lên; hạt giống vai trò; bảng mục tiêu `IT_WISHLIST` tồn tại; các hệ thống bên ngoài được khai báo khi cần thiết cho mô-đun này.
B14: 6 | C14: Thêm khóa học vào giỏ hàng | D14: IT_CART | E14: IT cho duy trì giỏ hàng (Controller–Service–Repository). Các trường hợp sử dụng: UC-46 Thêm khóa học vào giỏ hàng. Thành phần: StudentCommerceController, StudentCommerceService, CartItemRepository. Các trường hợp thử nghiệm trong bảng: 2. | F14: DB lên; hạt giống vai trò; bảng mục tiêu `IT_CART` tồn tại; các hệ thống bên ngoài được khai báo khi cần thiết cho mô-đun này.
B15: 7 | C15: Thanh toán (Checkout) | D15: IT_CHECKOUT | E15: IT cho báo giá/đặt hàng thanh toán và tính nhất quán của webhook (Controller–Service–Repository). Trường hợp sử dụng: Thanh toán UC-47. Thành phần: StudentPaymentController, PayosWebhookController, PaymentService, PaymentOrderRepository. Các trường hợp thử nghiệm trong trang tính: 5. | F15: DB lên; hạt giống vai trò; bảng mục tiêu `IT_CHECKOUT` tồn tại; các hệ thống bên ngoài được khai báo khi cần thiết cho mô-đun này.
B16: 8 | C16: Đăng ký tài khoản | D16: IT_AUTH | E16: IT cho đăng ký/đăng nhập/đặt lại mật khẩu (Controller–Service–Repository). Các trường hợp sử dụng: Đăng ký tài khoản UC-01, Đăng nhập UC-03, UC-04 Đặt lại mật khẩu. Thành phần: AuthController, AuthService, AuthTokenService, UserRepository, AuthTokenRepository. Các trường hợp thử nghiệm trong tờ: 9. | F16: DB lên; hạt giống vai trò; bảng mục tiêu `IT_AUTH` tồn tại; các hệ thống bên ngoài được khai báo khi cần thiết cho mô-đun này.
B17: 9 | C17: Quản lý hồ sơ | D17: IT_USER | E17: IT cho xem/cập nhật hồ sơ (Controller–Service–Repository). Ca sử dụng: UC-05 Quản lý hồ sơ. Thành phần: UserController, UserService, UserRepository. Các trường hợp kiểm thử trong sheet: 4. | F17: DB lên; hạt giống vai trò; bảng mục tiêu `IT_USER` tồn tại; các hệ thống bên ngoài được khai báo khi cần thiết cho mô-đun này.
B18: 10 | C18: Quản lý lớp học | D18: IT_CLASS | E18: IT cho lớp học nhân viên CRUD (Controller-Service-Repository). Các trường hợp sử dụng: UC-36a Tạo lớp học, UC-36b Xem lớp học, UC-36c Cập nhật lớp học. Thành phần: StaffClassroomController, ClassroomOfferingService, ClassroomOfferingRepository. Các trường hợp thử nghiệm trong trang tính: 3. | F18: DB lên; hạt giống vai trò; bảng mục tiêu `IT_CLASS` tồn tại; các hệ thống bên ngoài được khai báo khi cần thiết cho mô-đun này.
B19: 11 | C19: Phân công giáo viên vào lớp | D19: IT_ASNTEACH | E19: IT cho nhân viên phân công giáo viên vào lớp (Controller-Service-Repository). Các trường hợp sử dụng: UC-37 Phân công giáo viên vào lớp học. Thành phần: StaffClassroomController, ClassroomOfferingService, ClassroomTeacherAssignmentRepository. Các trường hợp thử nghiệm trong bảng: 2. | F19: DB lên; hạt giống vai trò; bảng mục tiêu `IT_ASNTEACH` tồn tại; các hệ thống bên ngoài được khai báo khi cần thiết cho mô-đun này.
B20: 12 | C20: Xem lịch giảng dạy | D20: IT_SCHEDULE | E20: IT cho lịch giảng dạy của giáo viên/lớp học được phân công (Controller-Service-Repository). Các trường hợp sử dụng: UC-22 Xem Lịch giảng dạy. Thành phần: TeacherClassroomController, ClassroomOfferingService, ClassroomSessionRepository. Các trường hợp thử nghiệm trong bảng: 2. | F20: DB lên; hạt giống vai trò; bảng mục tiêu `IT_SCHEDULE` tồn tại; các hệ thống bên ngoài được khai báo khi cần thiết cho mô-đun này.
... B35: 27 | C35: Xem báo cáo vận hành | D35: IT_REPORT | E35: IT cho bảng điều khiển hoạt động và phân tích doanh thu. Trường hợp sử dụng: UC-40 Xem báo cáo hoạt động, UC-41 Xem phân tích doanh thu của khóa học trực tuyến. Thành phần: StaffDashboardController, ContentManagerRevenueController, StaffOperationsService, PaymentService. Các trường hợp thử nghiệm trong bảng: 2. | F35: DB lên; hạt giống vai trò; bảng mục tiêu `IT_REPORT` tồn tại; các hệ thống bên ngoài được khai báo khi cần thiết cho mô-đun này.

Sheet Test Statistics
B1: THỐNG KÊ KIỂM THỬ
B3: Tên dự án | C3: =Cover!B4 | E3: Người tạo | F3: phongdx
B4: Mã dự án | C4: =Cover!B5 | E4: Người review / phê duyệt
B5: Mã tài liệu | C5: =C4&"_"&"Test Report"&"_"&"vx.x" | E5: Ngày ban hành | H5: 2026-08-06
B6: Ghi chú | C6: Gói kiểm tra tích hợp phát hành bao gồm 27 mô-đun: KHÓA HỌC, TRUY CẬP, ASSIGN, ĐĂNG KÝ, WISHLIST, CART, CHECKOUT, AUTH, USER, CLASS, ASNTEACH, SCHEDULE, ATTEND, MNGHW, TIMETABLE, MATERIAL, HOMEWORK, QUIZ, PLACEMENT, ONLINE, SYLLABUS, NOTIF, SUPPORT, ADMIN, BROADCAST, GMEET, BÁO CÁO. Mã mô-đun = Tên tính năng từ mỗi trang IT_* (Tiêu đề Ca sử dụng SRS). Đạt/Không đạt/Đang chờ xử lý/N/A được lấy từ Vòng 1 được tính trên mỗi tờ.
B10: STT | C10: Mã module | D10: Đạt | E10: Không đạt | F10: Chờ | G10: Không áp dụng | H10: Số lượng trường hợp thử nghiệm
B11: 1 | C11: =IT_COURSE!B2 | D11: =IT_COURSE!B6 | E11: =IT_COURSE!C6 | F11: =IT_COURSE!D6 | G11: =IT_COURSE!E6 | H11: =IT_COURSE!B4
B12: 2 | C12: =IT_ACCESS!B2 | D12: =IT_ACCESS!B6 | E12: =IT_ACCESS!C6 | F12: =IT_ACCESS!D6 | G12: =IT_ACCESS!E6 | H12: =IT_ACCESS!B4
B13: 3 | C13: =IT_ASSIGN!B2 | D13: =IT_ASSIGN!B6 | E13: =IT_ASSIGN!C6 | F13: =IT_ASSIGN!D6 | G13: =IT_ASSIGN!E6 | H13: =IT_ASSIGN!B4
B14: 4 | C14: =IT_ENROLL!B2 | D14: =IT_ENROLL!B6 | E14: =IT_ENROLL!C6 | F14: =IT_ENROLL!D6 | G14: =IT_ENROLL!E6 | H14: =IT_ENROLL!B4
B15: 5 | C15: =IT_WISHLIST!B2 | D15: =IT_WISHLIST!B6 | E15: =IT_WISHLIST!C6 | F15: =IT_WISHLIST!D6 | G15: =IT_WISHLIST!E6 | H15: =IT_WISHLIST!B4
B16: 6 | C16: =IT_CART!B2 | D16: =IT_CART!B6 | E16: =IT_CART!C6 | F16: =IT_CART!D6 | G16: =IT_CART!E6 | H16: =IT_CART!B4
B17: 7 | C17: =IT_CHECKOUT!B2 | D17: =IT_CHECKOUT!B6 | E17: =IT_CHECKOUT!C6 | F17: =IT_CHECKOUT!D6 | G17: =IT_CHECKOUT!E6 | H17: =IT_CHECKOUT!B4
B18: 8 | C18: =IT_AUTH!B2 | D18: =IT_AUTH!B6 | E18: =IT_AUTH!C6 | F18: =IT_AUTH!D6 | G18: =IT_AUTH!E6 | H18: =IT_AUTH!B4
B19: 9 | C19: =IT_USER!B2 | D19: =IT_USER!B6 | E19: =IT_USER!C6 | F19: =IT_USER!D6 | G19: =IT_USER!E6 | H19: =IT_USER!B4
B20: 10 | C20: =IT_CLASS!B2 | D20: =IT_CLASS!B6 | E20: =IT_CLASS!C6 | F20: =IT_CLASS!D6 | G20: =IT_CLASS!E6 | H20: =IT_CLASS!B4
B21: 11 | C21: =IT_ASNTEACH!B2 | D21: =IT_ASNTEACH!B6 | E21: =IT_ASNTEACH!C6 | F21: =IT_ASNTEACH!D6 | G21: =IT_ASNTEACH!E6 | H21: =IT_ASNTEACH!B4
B22: 12 | C22: =IT_SCHEDULE!B2 | D22: =IT_SCHEDULE!B6 | E22: =IT_SCHEDULE!C6 | F22: =IT_SCHEDULE!D6 | G22: =IT_SCHEDULE!E6 | H22: =IT_SCHEDULE!B4
B23: 13 | C23: =IT_ATTEND!B2 | D23: =IT_ATTEND!B6 | E23: =IT_ATTEND!C6 | F23: =IT_ATTEND!D6 | G23: =IT_ATTEND!E6 | H23: =IT_ATTEND!B4
B24: 14 | C24: =IT_MNGHW!B2 | D24: =IT_MNGHW!B6 | E24: =IT_MNGHW!C6 | F24: =IT_MNGHW!D6 | G24: =IT_MNGHW!E6 | H24: =IT_MNGHW!B4
B25: 15 | C25: =IT_TIMETABLE!B2 | D25: =IT_TIMETABLE!B6 | E25: =IT_TIMETABLE!C6 | F25: =IT_TIMETABLE!D6 | G25: =IT_TIMETABLE!E6 | H25: =IT_TIMETABLE!B4
B26: 16 | C26: =IT_MATERIAL!B2 | D26: =IT_MATERIAL!B6 | E26: =IT_MATERIAL!C6 | F26: =IT_MATERIAL!D6 | G26: =IT_MATERIAL!E6 | H26: =IT_MATERIAL!B4
B27: 17 | C27: =IT_HOMEWORK!B2 | D27: =IT_HOMEWORK!B6 | E27: =IT_HOMEWORK!C6 | F27: =IT_HOMEWORK!D6 | G27: =IT_HOMEWORK!E6 | H27: =IT_HOMEWORK!B4
B28: 18 | C28: =IT_QUIZ!B2 | D28: =IT_QUIZ!B6 | E28: =IT_QUIZ!C6 | F28: =IT_QUIZ!D6 | G28: =IT_QUIZ!E6 | H28: =IT_QUIZ!B4
B29: 19 | C29: =IT_PLACEMENT!B2 | D29: =IT_PLACEMENT!B6 | E29: =IT_PLACEMENT!C6 | F29: =IT_PLACEMENT!D6 | G29: =IT_PLACEMENT!E6 | H29: =IT_PLACEMENT!B4
B30: 20 | C30: =IT_ONLINE!B2 | D30: =IT_ONLINE!B6 | E30: =IT_ONLINE!C6 | F30: =IT_ONLINE!D6 | G30: =IT_ONLINE!E6 | H30: =IT_ONLINE!B4
B31: 21 | C31: =IT_SYLLABUS!B2 | D31: =IT_SYLLABUS!B6 | E31: =IT_SYLLABUS!C6 | F31: =IT_SYLLABUS!D6 | G31: =IT_SYLLABUS!E6 | H31: =IT_SYLLABUS!B4
B32: 22 | C32: =IT_NOTIF!B2 | D32: =IT_NOTIF!B6 | E32: =IT_NOTIF!C6 | F32: =IT_NOTIF!D6 | G32: =IT_NOTIF!E6 | H32: =IT_NOTIF!B4
B33: 23 | C33: =IT_SUPPORT!B2 | D33: =IT_SUPPORT!B6 | E33: =IT_SUPPORT!C6 | F33: =IT_SUPPORT!D6 | G33: =IT_SUPPORT!E6 | H33: =IT_SUPPORT!B4
B34: 24 | C34: =IT_ADMIN!B2 | D34: =IT_ADMIN!B6 | E34: =IT_ADMIN!C6 | F34: =IT_ADMIN!D6 | G34: =IT_ADMIN!E6 | H34: =IT_ADMIN!B4
B35: 25 | C35: =IT_BROADCAST!B2 | D35: =IT_BROADCAST!B6 | E35: =IT_BROADCAST!C6 | F35: =IT_BROADCAST!D6 | G35: =IT_BROADCAST!E6 | H35: =IT_BROADCAST!B4
B36: 26 | C36: =IT_GMEET!B2 | D36: =IT_GMEET!B6 | E36: =IT_GMEET!C6 | F36: =IT_GMEET!D6 | G36: =IT_GMEET!E6 | H36: =IT_GMEET!B4
B37: 27 | C37: =IT_REPORT!B2 | D37: =IT_REPORT!B6 | E37: =IT_REPORT!C6 | F37: =IT_REPORT!D6 | G37: =IT_REPORT!E6 | H37: =IT_REPORT!B4
C39: Tổng phụ | D39: =SUM(D11:D37) | E39: =SUM(E11:E37) | F39: =SUM(F11:F37) | G39: =SUM(G11:G37) | H39: =SUM(H11:H37)
C41: Phạm vi kiểm tra | E41: =IF((H39-G39)=0,0,(D39+E39)*100/(H39-G39)) | F41: %
C42: Kiểm tra vùng phủ sóng thành công | E42: =IF((H39-G39)=0,0,D39*100/(H39-G39)) | F42: %

Sheet IT_COURSE
A2: Chức năng (Feature) | B2: Xem khóa học công khai | R2: Passed
A3: Yêu cầu kiểm thử | B3: IT cho duyệt/tìm kiếm/chi tiết danh mục khóa học công cộng (Controller–Service–Repository). | R3: Failed
A4: Số lượng TC | B4: =COUNTIF(A11:A1000,"IT_*") | R4: Pending
A5: Vòng kiểm thử | B5: Đạt | C5: Không đạt | D5: Chờ | E5: Không áp dụng | R5: N/A
A6: Vòng 1 | B6: =COUNTIF($F11:$F993,B5) | C6: =COUNTIF($F11:$F993,C5) | D6: =COUNTIF($F11:$F993,D5) | E6: =COUNTIF($F11:$F993,E5)
A7: Vòng 2 | B7: =COUNTIF($I11:$I993,B5) | C7: =COUNTIF($I11:$I993,C5) | D7: =COUNTIF($I11:$I993,D5) | E7: =COUNTIF($I11:$I993,E5)
A8: Vòng 3 | B8: =COUNTIF($L11:$L993,B5) | C8: =COUNTIF($L11:$L993,C5) | D8: =COUNTIF($L11:$L993,D5) | E8: =COUNTIF($L11:$L993,E5)
A10: Mã Test Case | B10: Mô tả Test Case | C10: Các bước thực hiện | D10: Kết quả mong đợi | E10: Tiền điều kiện | F10: Vòng 1 | G10: Ngày test | H10: Người test | I10: Vòng 2 | J10: Ngày test | K10: Người test | L10: Vòng 3 | M10: Ngày test | N10: Người test | O10: Ghi chú
A11: Xem khóa học công khai
A12: IT_COURSE_01 | B12: Xác minh việc lấy danh sách khóa học công khai thông qua Controller. | C12: 1. Gọi GET /api/online-courses qua MockMvc (không cần xác thực). 2. PublicOnlineCourseController nhận request và gọi tiếp OnlineCourseService.getPublicCourses() (hoặc listPublicCourses). 3. OnlineCourseService truy vấn OnlineCourseRepository chỉ dành cho PUBLISHED/các khóa học đang hoạt động. 4. So sánh các ID khóa học được trả về với truy vấn DB trực tiếp của các khóa học PUBLISHED. | D12: HTTP status là 200 OK. Nội dung JSON là một danh sách/trang các khóa học. Chỉ PUBLISHED/khóa học đang hoạt động xuất hiện. DRAFT hoặc các khóa học chưa được xuất bản sẽ không xuất hiện. | E12: Cơ sở dữ liệu đã sẵn sàng. Ít nhất một khóa học PUBLISHED và một khóa học DRAFT tồn tại. | F12: Đạt | G12: 2026-08-07 | H12: phongdx | I12: Đạt | J12: 2026-08-07 | K12: phongdx | L12: Đạt | M12: 2026-08-07 | N12: phongdx | O12: danh mục công khai HTTP 200
A13: IT_COURSE_02 | B13: Xác minh việc lấy thông tin chi tiết khóa học công khai thông qua Controller. | C13: 1. Chọn slug hoặc id khóa học PUBLISHED đã biết từ cơ sở dữ liệu. 2. Gọi GET /api/online-courses/{slugOrId} qua MockMvc (không cần xác thực). 3. PublicOnlineCourseController gọi tiếp OnlineCourseService.getPublicCourse(). 4. OnlineCourseService tải khóa học từ OnlineCourseRepository. 5. Gọi GET /api/online-courses/{unknownSlug} qua MockMvc đối với trường hợp không tìm thấy. | D13: Đối với khóa học đã xuất bản hiện có: HTTP 200 OK và JSON chứa tiêu đề, giá cả, trạng thái. Các trường payload khớp với hàng OnlineCourseRepository. Đối với sên không xác định: HTTP 404 hoặc không tìm thấy doanh nghiệp (không phải 500). Không xảy ra ghi cơ sở dữ liệu (chỉ đọc). | E13: Ít nhất một khóa học đã xuất bản tồn tại trong DB. | F13: Đạt | G13: 2026-08-07 | H13: phongdx | I13: Đạt | J13: 2026-08-07 | K13: phongdx | L13: Đạt | M13: 2026-08-07 | N13: phongdx | O13: chi tiết khóa học HTTP 200
A14: IT_COURSE_03 | B14: Xác minh tìm kiếm/bộ lọc khóa học công khai qua Controller. | C14: 1. Chọn ít nhất hai khóa học PUBLISHED với các tiêu đề/danh mục khác nhau. 2. Gọi GET /api/online-courses?keyword={partOfTitle} qua MockMvc (không cần xác thực). 3. PublicOnlineCourseController gọi tiếp OnlineCourseService.getPublicCourses(keyword,...). 4. OnlineCourseService lọc OnlineCourseRepository theo từ khóa (và danh mục tùy chọn). 5. Tùy ý gọi GET /api/online-courses?category={categoryCode} và so sánh kết quả. | D14: HTTP status là 200 OK. Các khóa học được trả về khớp với bộ lọc từ khóa/danh mục. Các khóa học không phù hợp sẽ bị loại trừ. Vẫn chỉ có khóa học PUBLISHED xuất hiện. | E14: Có ít nhất hai khóa học được xuất bản với tiêu đề/danh mục có thể phân biệt được. | F14: Đạt | G14: 2026-08-07 | H14: phongdx | I14: Đạt | J14: 2026-08-07 | K14: phongdx | L14: Đạt | M14: 2026-08-07 | N14: phongdx | O14: từ khóa tìm kiếm HTTP 200
A15: IT_COURSE_04 | B15: Xác minh kết quả tìm kiếm trống trong danh mục công khai thông qua Controller. | C15: 1. Gọi GET /api/online-courses?keyword=__no_such_course_xyz__ qua MockMvc (không cần xác thực). 2. PublicOnlineCourseController gọi tiếp OnlineCourseService.getPublicCourses(). 3. OnlineCourseService truy vấn OnlineCourseRepository; không có hàng phù hợp. 4. Xác nhận phản hồi là danh sách/trang trống (Luồng thay thế SRS: không tìm thấy kết quả), không phải HTTP 500. | D15: HTTP status là 200 OK. Nội dung/danh sách trống (hoặc trang có totalElements=0). Không có HTTP 5xx. | E15: Không. | F15: Đạt | G15: 2026-08-07 | H15: phongdx | I15: Đạt | J15: 2026-08-07 | K15: phongdx | L15: Đạt | M15: 2026-08-07 | N15: phongdx | O15: tìm kiếm trống
A16: IT_COURSE_05 | B16: Xác minh danh sách các danh mục khóa học công khai qua Controller. | C16: 1. Gọi GET /api/online-courses/categories qua MockMvc (không cần xác thực). 2. PublicOnlineCourseController gọi tiếp CourseCategoryManagementService.getActiveCategories(). 3. Dịch vụ đọc các danh mục đang hoạt động từ kho danh mục. 4. So sánh mã/tên danh mục được trả về với các hàng DB đang hoạt động. | D16: HTTP status là 200 OK. Chỉ các danh mục hoạt động mới được trả về. Chỉ đọc: không ghi DB. | E16: Ít nhất một danh mục khóa học đang hoạt động tồn tại. | F16: Đạt | G16: 2026-08-07 | H16: phongdx | I16: Đạt | J16: 2026-08-07 | K16: phongdx | L16: Đạt | M16: 2026-08-07 | N16: phongdx | O16: danh mục HTTP 200

Sheet IT_ACCESS
A2: Chức năng (Feature) | B2: Truy cập tài liệu học online | R2: Passed
A3: Yêu cầu kiểm thử | B3: IT cho nội dung và tiến trình khóa học của người học đã đăng ký (Controller–Service–Repository). | R3: Failed
A4: Số lượng TC | B4: =COUNTIF(A11:A1000,"IT_*") | R4: Pending
A5: Vòng kiểm thử | B5: Đạt | C5: Không đạt | D5: Chờ | E5: Không áp dụng | R5: N/A
A6: Vòng 1 | B6: =COUNTIF($F11:$F993,B5) | C6: =COUNTIF($F11:$F993,C5) | D6: =COUNTIF($F11:$F993,D5) | E6: =COUNTIF($F11:$F993,E5)
A7: Vòng 2 | B7: =COUNTIF($I11:$I993,B5) | C7: =COUNTIF($I11:$I993,C5) | D7: =COUNTIF($I11:$I993,D5) | E7: =COUNTIF($I11:$I993,E5)
A8: Vòng 3 | B8: =COUNTIF($L11:$L993,B5) | C8: =COUNTIF($L11:$L993,C5) | D8: =COUNTIF($L11:$L993,D5) | E8: =COUNTIF($L11:$L993,E5)
A10: Mã Test Case | B10: Mô tả Test Case | C10: Các bước thực hiện | D10: Kết quả mong đợi | E10: Tiền điều kiện | F10: Vòng 1 | G10: Ngày test | H10: Người test | I10: Vòng 2 | J10: Ngày test | K10: Người test | L10: Vòng 3 | M10: Ngày test | N10: Người test | O10: Ghi chú
A11: Truy cập tài liệu học online
A12: IT_ACCESS_01 | B12: Xác minh người học đã đăng ký tải nội dung khóa học qua Controller. | C12: 1. Đăng nhập với tư cách là LEARNER đã đăng ký và nhận được JWT accessToken. 2. Gọi GET /api/student/online-courses/{courseId}/content qua MockMvc bằng token Authorization Bearer. 3. StudentOnlineCourseController gọi tiếp OnlineCourseService.getContentForLearner() (hoặc tương đương). 4. OnlineCourseService kiểm tra quyền sở hữu sau đó tải mô-đun/bài học từ kho lưu trữ liên quan. 5. Lặp lại thao tác GET tương tự (không cần xác thực), sau đó lặp lại với tư cách là LEARNER người chưa đăng ký. | D12: Cuộc gọi xác thực đã đăng ký: HTTP 200 OK với các mô-đun/bài học. Gọi không cần mã thông báo: HTTP 401 hoặc 403. Người học không đăng ký: HTTP 403 hoặc 404 và không có nội dung bài học được bảo vệ. | E12: LEARNER được ghi danh vào một khóa học có bài học. | F12: Đạt | G12: 2026-08-07 | H12: phongdx | I12: Đạt | J12: 2026-08-07 | K12: phongdx | L12: Đạt | M12: 2026-08-07 | N12: phongdx | O12: nội dung của người học HTTP 403
A13: IT_ACCESS_02 | B13: Xác minh tiến độ bài học tồn tại qua Controller. | C13: 1. Đăng nhập với tư cách là LEARNER đã đăng ký và nhận được JWT. 2. Gọi PATCH /api/student/online-courses/{courseId}/lessons/{lessonId}/progress qua MockMvc với nội dung tiến trình JSON và mã thông báo Bearer. 3. StudentOnlineCourseController gọi tiếp OnlineCourseService.saveLessonProgress(). 4. OnlineCourseService nâng cấp hàng tiến trình thông qua kho lưu trữ tiến trình. 5. Tải lại tiến trình (hoặc truy vấn DB) và thử lại PATCH tương tự như LEARNER chưa đăng ký. | D13: Cuộc gọi đã đăng ký: HTTP 2xx và hàng tiến trình được duy trì cho (sinh viên, khóa học, bài học). Các giá trị được tải lại khớp với nội dung yêu cầu. Cuộc gọi không được đăng ký: HTTP 403 hoặc 404 và không chèn tiến trình. | E13: Đã đăng ký LEARNER và tồn tại lessonId hợp lệ. | F13: Đạt | G13: 2026-08-07 | H13: phongdx | I13: Đạt | J13: 2026-08-07 | K13: phongdx | L13: Đạt | M13: 2026-08-07 | N13: phongdx | O13: tiến độ HTTP 403

Sheet IT_ASSIGN
A2: Chức năng (Feature) | B2: Xếp học viên vào lớp | R2: Passed
A3: Yêu cầu kiểm thử | B3: IT cho hàng đợi yêu cầu đăng ký nhân viên và phân công lớp học (Controller-Service-Repository). | R3: Failed
A4: Số lượng TC | B4: =COUNTIF(A11:A1000,"IT_*") | R4: Pending
A5: Vòng kiểm thử | B5: Đạt | C5: Không đạt | D5: Chờ | E5: Không áp dụng | R5: N/A
A6: Vòng 1 | B6: =COUNTIF($F11:$F996,B5) | C6: =COUNTIF($F11:$F996,C5) | D6: =COUNTIF($F11:$F996,D5) | E6: =COUNTIF($F11:$F996,E5)
A7: Vòng 2 | B7: =COUNTIF($I11:$I996,B5) | C7: =COUNTIF($I11:$I996,C5) | D7: =COUNTIF($I11:$I996,D5) | E7: =COUNTIF($I11:$I996,E5)
A8: Vòng 3 | B8: =COUNTIF($L11:$L996,B5) | C8: =COUNTIF($L11:$L996,C5) | D8: =COUNTIF($L11:$L996,D5) | E8: =COUNTIF($L11:$L996,E5)
A10: Mã Test Case | B10: Mô tả Test Case | C10: Các bước thực hiện | D10: Kết quả mong đợi | E10: Tiền điều kiện | F10: Vòng 1 | G10: Ngày test | H10: Người test | I10: Vòng 2 | J10: Ngày test | K10: Người test | L10: Vòng 3 | M10: Ngày test | N10: Người test | O10: Ghi chú
A11: Xếp học viên vào lớp
A12: IT_ASSIGN_01 | B12: Xác minh danh sách nhân viên yêu cầu đăng ký qua Controller. | C12: 1. Đăng nhập bằng STAFF và nhận JWT accessToken. 2. Gọi GET /api/staff/enrollment-requests qua MockMvc bằng token Authorization Bearer. 3. StaffEnrollmentRequestController nhận request và gọi tiếp EnrollmentRequestService.listForStaff(). 4. EnrollmentRequestService đọc các hàng từ EnrollmentRequestRepository. 5. Lặp lại GET tương tự như LEARNER (phải bị từ chối). | D12: STAFF lệnh gọi: HTTP 200 OK và danh sách JSON có id, trạng thái, tham chiếu người học. LEARNER gọi: HTTP 403 Forbidden. | E12: Vai trò STAFF đã được chọn. Tồn tại ít nhất một hàng đăng ký_requests. | F12: Đạt | G12: 2026-08-07 | H12: phongdx | I12: Đạt | J12: 2026-08-07 | K12: phongdx | L12: Đạt | M12: 2026-08-07 | N12: phongdx | O12: /api/staff/enrollment-requests
A13: IT_ASSIGN_02 | B13: Xác minh nhân viên lọc các yêu cầu đăng ký theo trạng thái qua Controller. | C13: 1. Yêu cầu đăng ký hạt giống với các trạng thái khác nhau (ví dụ SUBMITTED và WAITING_FOR_CLASS). 2. Đăng nhập bằng STAFF và nhận JWT. 3. Gọi GET /api/staff/enrollment-requests?status=WAITING_FOR_CLASS qua MockMvc. 4. StaffEnrollmentRequestController gọi tiếp EnrollmentRequestService bằng bộ lọc trạng thái. 5. EnrollmentRequestService truy vấn EnrollmentRequestRepository theo trạng thái. | D13: HTTP status là 200 OK. Mỗi hàng trả về đều có trạng thái WAITING_FOR_CLASS. | E13: Yêu cầu có nhiều trạng thái tồn tại. STAFF JWT có sẵn. | F13: Đạt | G13: 2026-08-07 | H13: phongdx | I13: Đạt | J13: 2026-08-07 | K13: phongdx | L13: Đạt | M13: 2026-08-07 | N13: phongdx | O13: đăng ký bộ lọc/danh sách HTTP 200
A14: IT_ASSIGN_03 | B14: Xác minh nhân viên phân công người học vào lớp qua Controller. | C14: 1. Gửi yêu cầu đăng ký WAITING_FOR_CLASS và một lớp học đã được phê duyệt có chỗ ngồi miễn phí. 2. Đăng nhập bằng STAFF và nhận JWT. 3. Gọi PATCH /api/staff/enrollment-requests/{requestId}/assign-class qua MockMvc với phần thân chứa classroomId. 4. StaffEnrollmentRequestController gọi tiếp EnrollmentRequestService.assignToClassroom(). 5. EnrollmentRequestService cập nhật EnrollmentRequestRepository và tạo đăng ký lớp học thông qua ClassroomOfferingService / kho lưu trữ đăng ký. | D14: HTTP status là 200 hoặc 201. Trạng thái yêu cầu trở thành CLASS_ASSIGNED (hoặc tương đương). Có chính xác một hàng ghi danh lớp học cho người học và lớp đó. Nếu lớp học đã đầy: HTTP 4xx và không chèn tuyển sinh. | E14: Có yêu cầu WAITING_FOR_CLASS đủ điều kiện và có lớp học có chỗ ngồi miễn phí. | F14: Đạt | G14: 2026-08-07 | H14: phongdx | I14: Đạt | J14: 2026-08-07 | K14: phongdx | L14: Đạt | M14: 2026-08-07 | N14: phongdx | O14: chỉ định lớp học có điều kiện trước HTTP 200
A15: IT_ASSIGN_04 | B15: Xác minh nhân viên từ chối yêu cầu đăng ký qua Controller. | C15: 1. Gửi yêu cầu đăng ký mở. 2. Đăng nhập bằng STAFF và nhận JWT. 3. Gọi PATCH /api/staff/enrollment-requests/{requestId}/reject qua MockMvc với phần thân lý do không trống. 4. StaffEnrollmentRequestController gọi tiếp EnrollmentRequestService.reject(). 5. EnrollmentRequestService cập nhật trạng thái và lý do trong EnrollmentRequestRepository, sau đó thử gán theo cùng một yêu cầu. | D15: Từ chối cuộc gọi: HTTP 200 OK, trạng thái ĐÃ TỪ CHỐI, lý do được lưu trữ. Cuộc gọi chỉ định sau: HTTP 4xx và không có đăng ký lớp học nào được tạo. | E15: Đã tồn tại một yêu cầu đăng ký mở. STAFF JWT có sẵn. | F15: Đạt | G15: 2026-08-07 | H15: phongdx | I15: Đạt | J15: 2026-08-07 | K15: phongdx | L15: Đạt | M15: 2026-08-07 | N15: phongdx | O15: /api/staff/enrollment-requests

Sheet IT_ENROLL
A2: Chức năng (Feature) | B2: Đăng ký khóa học | R2: Passed
A3: Yêu cầu kiểm thử | B3: IT cho yêu cầu đăng ký của người học và đăng ký của tôi (Controller–Service–Repository). | R3: Failed
A4: Số lượng TC | B4: =COUNTIF(A11:A1000,"IT_*") | R4: Pending
A5: Vòng kiểm thử | B5: Đạt | C5: Không đạt | D5: Chờ | E5: Không áp dụng | R5: N/A
A6: Vòng 1 | B6: =COUNTIF($F11:$F993,B5) | C6: =COUNTIF($F11:$F993,C5) | D6: =COUNTIF($F11:$F993,D5) | E6: =COUNTIF($F11:$F993,E5)
A7: Vòng 2 | B7: =COUNTIF($I11:$I993,B5) | C7: =COUNTIF($I11:$I993,C5) | D7: =COUNTIF($I11:$I993,D5) | E7: =COUNTIF($I11:$I993,E5)
A8: Vòng 3 | B8: =COUNTIF($L11:$L993,B5) | C8: =COUNTIF($L11:$L993,C5) | D8: =COUNTIF($L11:$L993,D5) | E8: =COUNTIF($L11:$L993,E5)
A10: Mã Test Case | B10: Mô tả Test Case | C10: Các bước thực hiện | D10: Kết quả mong đợi | E10: Tiền điều kiện | F10: Vòng 1 | G10: Ngày test | H10: Người test | I10: Vòng 2 | J10: Ngày test | K10: Người test | L10: Vòng 3 | M10: Ngày test | N10: Người test | O10: Ghi chú
A11: Đăng ký khóa học
A12: IT_ENROLL_01 | B12: Xác minh người học gửi yêu cầu đăng ký qua Controller. | C12: 1. Đăng nhập bằng LEARNER và nhận JWT. 2. Gọi POST /api/student/course-enrollment-requests với các trường JSON bắt buộc thông qua MockMvc. 3. StudentEnrollmentRequestController gọi tiếp EnrollmentRequestService.create(). 4. EnrollmentRequestService lưu một hàng mới thông qua EnrollmentRequestRepository do người dùng hiện tại sở hữu. 5. Thử lại với các trường bắt buộc bị thiếu, sau đó thử lại (không cần xác thực). | D12: ĐĂNG hợp lệ: HTTP 200 hoặc 201 và một hàng đăng ký_requests mới có trạng thái SUBMITTED mặc định. Tải trọng không hợp lệ: HTTP 400 và không chèn. Không được phép: HTTP 401 hoặc 403. | E12: LEARNER đã đăng nhập. Tồn tại một khóa họcOfferingId hợp lệ. | F12: Đạt | G12: 2026-08-07 | H12: phongdx | I12: Đạt | J12: 2026-08-07 | K12: phongdx | L12: Đạt | M12: 2026-08-07 | N12: phongdx | O12: tạo yêu cầu đăng ký HTTP 400
A13: IT_ENROLL_02 | B13: Xác minh danh sách đăng ký của tôi qua Controller. | C13: 1. Tuyển sinh ban đầu cho người học A và người học B vào các khóa học khác nhau. 2. Đăng nhập với tư cách là người học A và gọi GET /api/student/online-courses/my-enrollments qua MockMvc bằng mã thông báo Bearer. 3. StudentOnlineCourseController gọi tiếp OnlineCourseService.listMyEnrollments(). 4. OnlineCourseService truy vấn dữ liệu đăng ký trong phạm vi id người dùng hiện tại. | D13: HTTP status là 200 OK. Chỉ có các khóa học của người học A được trả lại. Các khóa học dành cho người học B không xuất hiện (không có rò rỉ giữa người dùng chéo). | E13: Tồn tại hai tài khoản LEARNER có số lần đăng ký khác nhau. | F13: Đạt | G13: 2026-08-07 | H13: phongdx | I13: Đạt | J13: 2026-08-07 | K13: phongdx | L13: Đạt | M13: 2026-08-07 | N13: phongdx | O13: đăng ký của tôi HTTP 200

Sheet IT_WISHLIST
A2: Chức năng (Feature) | B2: Danh sách yêu thích khóa học | R2: Passed
A3: Yêu cầu kiểm thử | B3: IT cho duy trì danh sách mong muốn (Controller–Service–Repository). | R3: Failed
A4: Số lượng TC | B4: =COUNTIF(A11:A1000,"IT_*") | R4: Pending
A5: Vòng kiểm thử | B5: Đạt | C5: Không đạt | D5: Chờ | E5: Không áp dụng | R5: N/A
A6: Vòng 1 | B6: =COUNTIF($F11:$F994,B5) | C6: =COUNTIF($F11:$F994,C5) | D6: =COUNTIF($F11:$F994,D5) | E6: =COUNTIF($F11:$F994,E5)
A7: Vòng 2 | B7: =COUNTIF($I11:$I994,B5) | C7: =COUNTIF($I11:$I994,C5) | D7: =COUNTIF($I11:$I994,D5) | E7: =COUNTIF($I11:$I994,E5)
A8: Vòng 3 | B8: =COUNTIF($L11:$L994,B5) | C8: =COUNTIF($L11:$L994,C5) | D8: =COUNTIF($L11:$L994,D5) | E8: =COUNTIF($L11:$L994,E5)
A10: Mã Test Case | B10: Mô tả Test Case | C10: Các bước thực hiện | D10: Kết quả mong đợi | E10: Tiền điều kiện | F10: Vòng 1 | G10: Ngày test | H10: Người test | I10: Vòng 2 | J10: Ngày test | K10: Người test | L10: Vòng 3 | M10: Ngày test | N10: Người test | O10: Ghi chú
A11: Danh sách yêu thích khóa học
A12: IT_WISHLIST_01 | B12: Xác minh việc thêm khóa học vào danh sách mong muốn qua Controller. | C12: 1. Đăng nhập bằng LEARNER và nhận JWT. 2. Gọi POST /api/student/commerce/wishlist/{courseId} qua MockMvc bằng Bearer token. 3. StudentCommerceController gọi tiếp StudentCommerceService.addToWishlist(). 4. StudentCommerceService lưu mục thông qua WishlistItemRepository. | D12: HTTP status là 200 hoặc 201. Một hàng danh sách mong muốn tồn tại cho người dùng hiện tại và khóa học. | E12: LEARNER đã đăng nhập. Đã tồn tại một khóa học đã xuất bản. | F12: Đạt | G12: 2026-08-07 | H12: phongdx | I12: Đạt | J12: 2026-08-07 | K12: phongdx | L12: Đạt | M12: 2026-08-07 | N12: phongdx | O12: di chuyển vào giỏ hàng HTTP 200
A13: IT_WISHLIST_02 | B13: Xác minh danh sách mong muốn qua Controller. | C13: 1. Đăng nhập bằng LEARNER và nhận JWT. 2. Gọi GET /api/student/commerce/wishlist qua MockMvc bằng mã thông báo Bearer. 3. StudentCommerceController gọi tiếp StudentCommerceService.listWishlist(). 4. StudentCommerceService đọc WishlistItemRepository trong phạm vi người dùng hiện tại. | D13: HTTP status là 200 OK. Chỉ các mục trong danh sách mong muốn của người học hiện tại mới được trả lại. | E13: Danh sách mong muốn của người học có ít nhất một mục. | F13: Đạt | G13: 2026-08-07 | H13: phongdx | I13: Đạt | J13: 2026-08-07 | K13: phongdx | L13: Đạt | M13: 2026-08-07 | N13: phongdx | O13: danh sách mong muốn HTTP 200

Sheet IT_CART
A2: Chức năng (Feature) | B2: Thêm khóa học vào giỏ hàng | R2: Passed
A3: Yêu cầu kiểm thử | B3: IT cho duy trì giỏ hàng (Controller–Service–Repository). | R3: Failed
A4: Số lượng TC | B4: =COUNTIF(A11:A1000,"IT_*") | R4: Pending
A5: Vòng kiểm thử | B5: Đạt | C5: Không đạt | D5: Chờ | E5: Không áp dụng | R5: N/A
A6: Vòng 1 | B6: =COUNTIF($F11:$F994,B5) | C6: =COUNTIF($F11:$F994,C5) | D6: =COUNTIF($F11:$F994,D5) | E6: =COUNTIF($F11:$F994,E5)
A7: Vòng 2 | B7: =COUNTIF($I11:$I994,B5) | C7: =COUNTIF($I11:$I994,C5) | D7: =COUNTIF($I11:$I994,D5) | E7: =COUNTIF($I11:$I994,E5)
A8: Vòng 3 | B8: =COUNTIF($L11:$L994,B5) | C8: =COUNTIF($L11:$L994,C5) | D8: =COUNTIF($L11:$L994,D5) | E8: =COUNTIF($L11:$L994,E5)
A10: Mã Test Case | B10: Mô tả Test Case | C10: Các bước thực hiện | D10: Kết quả mong đợi | E10: Tiền điều kiện | F10: Vòng 1 | G10: Ngày test | H10: Người test | I10: Vòng 2 | J10: Ngày test | K10: Người test | L10: Vòng 3 | M10: Ngày test | N10: Người test | O10: Ghi chú
A11: Thêm khóa học vào giỏ hàng
A12: IT_CART_01 | B12: Xác minh việc thêm khóa học vào giỏ hàng qua Controller. | C12: 1. Đăng nhập bằng LEARNER và nhận JWT. 2. Gọi POST /api/student/commerce/cart/{courseId} qua MockMvc bằng Bearer token. 3. StudentCommerceController gọi tiếp StudentCommerceService.addToCart(). 4. StudentCommerceService lưu qua CartItemRepository. | D12: HTTP status là 200 hoặc 201. Một hàng mục giỏ hàng tồn tại cho người dùng hiện tại. | E12: LEARNER đã đăng nhập. Đã tồn tại một khóa học đã xuất bản. | F12: Đạt | G12: 2026-08-07 | H12: phongdx | I12: Đạt | J12: 2026-08-07 | K12: phongdx | L12: Đạt | M12: 2026-08-07 | N12: phongdx | O12: giỏ hàng nhận được HTTP 200
A13: IT_CART_02 | B13: Xác minh việc xóa mục giỏ hàng qua Controller. | C13: 1. Đăng nhập bằng LEARNER và nhận JWT. 2. Gọi DELETE /api/student/commerce/cart/{courseId} qua MockMvc bằng mã thông báo Bearer. 3. StudentCommerceController gọi tiếp StudentCommerceService.removeFromCart(). 4. StudentCommerceService xóa hàng qua CartItemRepository. | D13: HTTP status là 200 hoặc 204. Mục giỏ hàng không còn tồn tại cho người dùng đó. | E13: Giỏ hàng chứa mặt hàng mục tiêu. | F13: Đạt | G13: 2026-08-07 | H13: phongdx | I13: Đạt | J13: 2026-08-07 | K13: phongdx | L13: Đạt | M13: 2026-08-07 | N13: phongdx | O13: loại bỏ giỏ hàng

Sheet IT_CHECKOUT
A2: Chức năng (Feature) | B2: Thanh toán (Checkout) | R2: Passed
A3: Yêu cầu kiểm thử | B3: IT cho báo giá/đặt hàng thanh toán và tính nhất quán của webhook (Controller–Service–Repository). | R3: Failed
A4: Số lượng TC | B4: =COUNTIF(A11:A1000,"IT_*") | R4: Pending
A5: Vòng kiểm thử | B5: Đạt | C5: Không đạt | D5: Chờ | E5: Không áp dụng | R5: N/A
A6: Vòng 1 | B6: =COUNTIF($F11:$F997,B5) | C6: =COUNTIF($F11:$F997,C5) | D6: =COUNTIF($F11:$F997,D5) | E6: =COUNTIF($F11:$F997,E5)
A7: Vòng 2 | B7: =COUNTIF($I11:$I997,B5) | C7: =COUNTIF($I11:$I997,C5) | D7: =COUNTIF($I11:$I997,D5) | E7: =COUNTIF($I11:$I997,E5)
A8: Vòng 3 | B8: =COUNTIF($L11:$L997,B5) | C8: =COUNTIF($L11:$L997,C5) | D8: =COUNTIF($L11:$L997,D5) | E8: =COUNTIF($L11:$L997,E5)
A10: Mã Test Case | B10: Mô tả Test Case | C10: Các bước thực hiện | D10: Kết quả mong đợi | E10: Tiền điều kiện | F10: Vòng 1 | G10: Ngày test | H10: Người test | I10: Vòng 2 | J10: Ngày test | K10: Người test | L10: Vòng 3 | M10: Ngày test | N10: Người test | O10: Ghi chú
A11: Thanh toán (Checkout)
A12: IT_CHECKOUT_01 | B12: Xác minh việc tạo báo giá/đơn hàng thanh toán qua Controller. | C12: 1. Đăng nhập bằng LEARNER với giỏ hàng không trống và nhận JWT. 2. Gọi POST /api/student/payments/quote qua MockMvc bằng mã thông báo Bearer (hoặc POST /api/student/payments/payos/link để thanh toán). 3. StudentPaymentController gọi tiếp PaymentService.createOrder() (hoặc tương đương). 4. PaymentService duy trì PaymentOrder thông qua PaymentOrderRepository. | D12: HTTP status là 200 hoặc 201. Một hàng lệnh thanh toán tồn tại với trạng thái ĐANG CHỜ (hoặc tương đương) và số tiền chính xác. | E12: LEARNER giỏ hàng có các mặt hàng phải trả. | F12: Đạt | G12: 2026-08-07 | H12: phongdx | I12: Đạt | J12: 2026-08-07 | K12: phongdx | L12: Đạt | M12: 2026-08-07 | N12: phongdx | O12: trích dẫn với CourseIds HTTP 200
A13: IT_CHECKOUT_02 | B13: Xác minh danh sách các lệnh thanh toán của tôi qua Controller. | C13: 1. Đăng nhập bằng LEARNER và nhận JWT. 2. Gọi GET /api/student/payments/orders qua MockMvc bằng mã thông báo Bearer. 3. StudentPaymentController gọi tiếp PaymentService.listMyOrders(). 4. PaymentService truy vấn PaymentOrderRepository bởi người dùng hiện tại. | D13: HTTP status là 200 OK. Chỉ các đơn đặt hàng của người học hiện tại được trả lại. | E13: Ít nhất một lệnh thanh toán tồn tại cho người học. | F13: Đạt | G13: 2026-08-07 | H13: phongdx | I13: Đạt | J13: 2026-08-07 | K13: phongdx | L13: Đạt | M13: 2026-08-07 | N13: phongdx | O13: đơn đặt hàng của tôi HTTP 200
A14: IT_CHECKOUT_03 | B14: Xác minh việc thanh toán bị từ chối do giỏ hàng trống qua Controller. | C14: 1. Đăng nhập bằng LEARNER với giỏ hàng trống và nhận JWT. 2. Gọi POST /api/student/payments/payos/link qua MockMvc bằng Bearer token. 3. StudentPaymentController gọi tiếp PaymentService; xác thực không thành công trước khi lưu. 4. Xác nhận PaymentOrderRepository không có hàng mới cho cuộc gọi này. | D14: HTTP status là 4xx. Không có hàng PaymentOrder mới nào được tạo. | E14: LEARNER có một giỏ hàng trống. | F14: Đạt | G14: 2026-08-07 | H14: phongdx | I14: Đạt | J14: 2026-08-07 | K14: phongdx | L14: Đạt | M14: 2026-08-07 | N14: phongdx | O14: giỏ hàng trống bị từ chối HTTP 400
A15: IT_CHECKOUT_04 | B15: Xác minh trạng thái đơn hàng cập nhật webhook PayOS qua Controller. | C15: 1. Chuẩn bị id lệnh thanh toán đang chờ xử lý trong cơ sở dữ liệu. 2. Gọi POST /api/payos/webhook (hoặc đường dẫn webhook dự án PayOS) qua MockMvc với hộp cát hoặc payload sơ khai. 3. PayosWebhookController gọi tiếp PaymentService.handleWebhook(). 4. PaymentService cập nhật trạng thái đơn hàng trong PaymentOrderRepository. | D15: HTTP status là 200. Trạng thái đơn hàng trong DB khớp với kết quả webhook. Việc phát lại cùng một webhook không gây ra tác dụng phụ. | E15: Đang tồn tại một lệnh thanh toán đang chờ xử lý. Sơ khai webhook hoặc hộp cát được bật. | F15: Đạt | G15: 2026-08-07 | H15: phongdx | I15: Đạt | J15: 2026-08-07 | K15: phongdx | L15: Đạt | M15: 2026-08-07 | N15: phongdx | O15: webhook có thể truy cập được HTTP 400
A16: IT_CHECKOUT_05 | B16: Xác minh việc thanh toán trái phép bị chặn qua Controller. | C16: 1. Gọi POST /api/student/payments/payos/link qua MockMvc (không cần xác thực). 2. Bộ lọc bảo mật từ chối yêu cầu trước logic nghiệp vụ StudentPaymentController. 3. Xác nhận PaymentOrderRepository không có phần chèn nào từ cuộc gọi này. | D16: HTTP status là 401 hoặc 403. Không có thao tác chèn PaymentOrder nào xảy ra. | E16: Không. | F16: Đạt | G16: 2026-08-07 | H16: phongdx | I16: Đạt | J16: 2026-08-07 | K16: phongdx | L16: Đạt | M16: 2026-08-07 | N16: phongdx | O16: thanh toán không xác thực HTTP 403

Sheet IT_AUTH
A2: Chức năng (Feature) | B2: Đăng ký tài khoản | R2: Passed
A3: Yêu cầu kiểm thử | B3: IT cho đăng ký/đăng nhập/đặt lại mật khẩu (Controller–Service–Repository). | R3: Failed
A4: Số lượng TC | B4: =COUNTIF(A11:A1000,"IT_*") | R4: Pending
A5: Vòng kiểm thử | B5: Đạt | C5: Không đạt | D5: Chờ | E5: Không áp dụng | R5: N/A
A6: Vòng 1 | B6: =COUNTIF($F11:$F997,B5) | C6: =COUNTIF($F11:$F997,C5) | D6: =COUNTIF($F11:$F997,D5) | E6: =COUNTIF($F11:$F997,E5)
A7: Vòng 2 | B7: =COUNTIF($I11:$I997,B5) | C7: =COUNTIF($I11:$I997,C5) | D7: =COUNTIF($I11:$I997,D5) | E7: =COUNTIF($I11:$I997,E5)
A8: Vòng 3 | B8: =COUNTIF($L11:$L997,B5) | C8: =COUNTIF($L11:$L997,C5) | D8: =COUNTIF($L11:$L997,D5) | E8: =COUNTIF($L11:$L997,E5)
A10: Mã Test Case | B10: Mô tả Test Case | C10: Các bước thực hiện | D10: Kết quả mong đợi | E10: Tiền điều kiện | F10: Vòng 1 | G10: Ngày test | H10: Người test | I10: Vòng 2 | J10: Ngày test | K10: Người test | L10: Vòng 3 | M10: Ngày test | N10: Người test | O10: Ghi chú
A11: Đăng ký tài khoản
A12: IT_AUTH_01 | B12: Xác minh đăng ký tài khoản mới qua Controller. | C12: 1. Chuẩn bị một email duy nhất không có trong cơ sở dữ liệu. 2. Gọi POST /api/auth/register với JSON hợp lệ qua MockMvc. 3. AuthController gọi tiếp AuthService.register(). 4. AuthService lưu người dùng thông qua UserRepository (mật khẩu được hash) và có thể tạo token xác minh trong AuthTokenRepository. | D12: HTTP status là 2xx. Một hàng người dùng được lưu. Mật khẩu được lưu trữ dưới dạng hash, không phải plain text. | E12: Email chưa được đăng ký. | F12: Đạt | G12: 2026-08-07 | H12: phongdx | I12: Đạt | J12: 2026-08-07 | K12: phongdx | L12: Đạt | M12: 2026-08-07 | N12: phongdx | O12: đăng ký HTTP 200
A13: IT_AUTH_02 | B13: Xác minh đăng ký trùng lặp bị từ chối qua Controller. | C13: 1. Gọi POST /api/auth/register bằng email đã tồn tại qua MockMvc. 2. AuthController gọi tiếp AuthService.register(). 3. AuthService kiểm tra tính duy nhất đối với UserRepository và từ chối yêu cầu. | D13: HTTP status là 4xx. Không có hàng người dùng thứ hai nào được tạo cho cùng một email. | E13: Email đã tồn tại trong DB. | F13: Đạt | G13: 2026-08-07 | H13: phongdx | I13: Đạt | J13: 2026-08-07 | K13: phongdx | L13: Đạt | M13: 2026-08-07 | N13: phongdx | O13: đăng ký trùng lặp HTTP 400
A14: IT_AUTH_03 | B14: Xác minh xác minh email OTP qua Controller. | C14: 1. Đăng ký người dùng mới chưa được xác minh, sau đó gọi POST /api/auth/verify-email với mã hợp lệ qua MockMvc. 2. AuthController gọi tiếp AuthService.verifyEmail(). 3. AuthService xác thực mã thông báo trong AuthTokenRepository và cập nhật cờ đã xác minh trong UserRepository. | D14: HTTP status là 200. Người dùng được đánh dấu đã xác minh. Mã thông báo OTP đã được sử dụng hoặc không hợp lệ. | E14: Người dùng chưa được xác minh và OTP hợp lệ có sẵn. | F14: Đạt | G14: 2026-08-07 | H14: phongdx | I14: Đạt | J14: 2026-08-07 | K14: phongdx | L14: Đạt | M14: 2026-08-07 | N14: phongdx | O14: Được chuyển qua MockMvc: đăng ký → đọc EMAIL_VERIFICATION OTP từ auth_tokens → POST /api/auth/verify-email
A15: IT_AUTH_04 | B15: Xác minh OTP không hợp lệ bị từ chối qua Controller. | C15: 1. Gọi POST /api/auth/verify-email với mã sai qua MockMvc. 2. AuthController gọi tiếp AuthService.verifyEmail(). 3. AuthService không xác thực được mã thông báo đối với AuthTokenRepository. | D15: HTTP status là 4xx. Người dùng vẫn chưa được xác minh. | E15: Một người dùng chưa được xác minh tồn tại. | F15: Đạt | G15: 2026-08-07 | H15: phongdx | I15: Đạt | J15: 2026-08-07 | K15: phongdx | L15: Đạt | M15: 2026-08-07 | N15: phongdx | O15: không hợp lệ OTP HTTP 400
A16: Đăng nhập
A17: IT_AUTH_05 | B17: Xác minh đăng nhập trả về mã thông báo truy cập qua Controller. | C17: 1. Gọi POST /api/auth/login bằng email và mật khẩu hợp lệ qua MockMvc. 2. AuthController gọi tiếp AuthService.login(). 3. AuthService tải người dùng từ UserRepository và đưa ra JWT accessToken. | D17: HTTP status là 200 OK. JSON chứa accessToken. | E17: Đã tồn tại một người dùng đã được xác minh với mật khẩu đã biết. | F17: Đạt | G17: 2026-08-07 | H17: phongdx | I17: Đạt | J17: 2026-08-07 | K17: phongdx | L17: Đạt | M17: 2026-08-07 | N17: phongdx | O17: đăng nhập+tôi HTTP 200
A18: IT_AUTH_06 | B18: Xác minh /api/user/me bằng JWT qua Controller. | C18: 1. Đăng nhập và nhận JWT accessToken. 2. Gọi GET /api/user/me qua MockMvc bằng token Authorization Bearer. 3. UserController gọi tiếp UserService.getCurrentUser(). 4. UserService tải hồ sơ từ UserRepository. | D18: HTTP status là 200 OK. Email JSON khớp với người dùng đã đăng nhập. | E18: Có sẵn JWT hợp lệ khi đăng nhập. | F18: Đạt | G18: 2026-08-07 | H18: phongdx | I18: Đạt | J18: 2026-08-07 | K18: phongdx | L18: Đạt | M18: 2026-08-07 | N18: phongdx | O18: mật khẩu sai HTTP 401
A19: IT_AUTH_07 | B19: Xác minh đăng nhập với mật khẩu sai bị từ chối qua Controller. | C19: 1. Gọi POST /api/auth/login sai mật khẩu qua MockMvc. 2. AuthController gọi tiếp AuthService.login(). 3. AuthService không kiểm tra được thông tin xác thực đối với UserRepository. | D19: HTTP status là 401 hoặc 4xx. Không có accessToken nào được phát hành. | E19: Một tài khoản người dùng hiện có sẵn. | F19: Đạt | G19: 2026-08-07 | H19: phongdx | I19: Đạt | J19: 2026-08-07 | K19: phongdx | L19: Đạt | M19: 2026-08-07 | N19: phongdx | O19: tôi không có mã thông báo HTTP 403
A20: Đặt lại mật khẩu
A21: IT_AUTH_08 | B21: Xác minh yêu cầu quên mật khẩu qua Controller. | C21: 1. Gọi POST /api/auth/forgot-password bằng email đã đăng ký qua MockMvc. 2. AuthController gọi tiếp AuthService.forgotPassword(). 3. AuthService tạo mã thông báo đặt lại thông qua AuthTokenRepository. | D21: HTTP status là 200 (hoặc thành công chung). Hàng mã thông báo đặt lại tồn tại cho người dùng. | E21: Email đã đăng ký tồn tại. | F21: Đạt | G21: 2026-08-07 | H21: phongdx | I21: Đạt | J21: 2026-08-07 | K21: phongdx | L21: Đạt | M21: 2026-08-07 | N21: phongdx | O21: quên mật khẩu HTTP 400
A22: IT_AUTH_09 | B22: Xác minh đặt lại mật khẩu bằng mã thông báo qua Controller. | C22: 1. Gọi POST /api/auth/reset-password bằng mã thông báo hợp lệ và mật khẩu mới qua MockMvc. 2. AuthController gọi tiếp AuthService.resetPassword(). 3. AuthService cập nhật hàm băm mật khẩu trong UserRepository và vô hiệu hóa mã thông báo trong AuthTokenRepository. 4. Đăng nhập bằng mật khẩu mới, sau đó xác nhận mật khẩu cũ không thành công. | D22: HTTP status là 200. Đăng nhập thành công với mật khẩu mới. Đăng nhập không thành công với mật khẩu cũ. | E22: Mã thông báo đặt lại hợp lệ tồn tại. | F22: Đạt | G22: 2026-08-07 | H22: phongdx | I22: Đạt | J22: 2026-08-07 | K22: phongdx | L22: Đạt | M22: 2026-08-07 | N22: phongdx | O22: Đã chuyển qua MockMvc: đăng ký+xác minh → quên → đọc PASSWORD_RESET OTP từ auth_tokens → đặt lại mật khẩu → đăng nhập mật khẩu mới

Sheet IT_USER
A2: Chức năng (Feature) | B2: Quản lý hồ sơ | R2: Passed
A3: Yêu cầu kiểm thử | B3: IT cho xem/cập nhật hồ sơ (Controller–Service–Repository). | R3: Failed
A4: Số lượng TC | B4: =COUNTIF(A11:A1000,"IT_*") | R4: Pending
A5: Vòng kiểm thử | B5: Đạt | C5: Không đạt | D5: Chờ | E5: Không áp dụng | R5: N/A
A6: Vòng 1 | B6: =COUNTIF($F11:$F995,B5) | C6: =COUNTIF($F11:$F995,C5) | D6: =COUNTIF($F11:$F995,D5) | E6: =COUNTIF($F11:$F995,E5)
A7: Vòng 2 | B7: =COUNTIF($I11:$I995,B5) | C7: =COUNTIF($I11:$I995,C5) | D7: =COUNTIF($I11:$I995,D5) | E7: =COUNTIF($I11:$I995,E5)
A8: Vòng 3 | B8: =COUNTIF($L11:$L995,B5) | C8: =COUNTIF($L11:$L995,C5) | D8: =COUNTIF($L11:$L995,D5) | E8: =COUNTIF($L11:$L995,E5)
A10: Mã Test Case | B10: Mô tả Test Case | C10: Các bước thực hiện | D10: Kết quả mong đợi | E10: Tiền điều kiện | F10: Vòng 1 | G10: Ngày test | H10: Người test | I10: Vòng 2 | J10: Ngày test | K10: Người test | L10: Vòng 3 | M10: Ngày test | N10: Người test | O10: Ghi chú
A11: Quản lý hồ sơ
A12: IT_USER_01 | B12: Xác minh việc tìm nạp hồ sơ người dùng qua Controller. | C12: 1. Đăng nhập và nhận JWT accessToken. 2. Gọi GET /api/user/me qua MockMvc bằng token Authorization Bearer. 3. UserController gọi tiếp UserService.getCurrentUser() hoặc findById(). 4. UserService truy xuất người dùng từ UserRepository. | D12: HTTP status là 200 OK. JSON trả về chứa thông tin người dùng chính xác (tên, email). | E12: Người dùng tồn tại trong DB. | F12: Đạt | G12: 2026-08-07 | H12: phongdx | I12: Đạt | J12: 2026-08-07 | K12: phongdx | L12: Đạt | M12: 2026-08-07 | N12: phongdx | O12: NHẬN TÔI HTTP 200
A13: IT_USER_02 | B13: Xác minh hồ sơ cập nhật vẫn lưu dữ liệu vào DB. | C13: 1. Đăng nhập và lấy JWT. 2. Gọi PUT hoặc PATCH /api/user/me với payload JSON hợp lệ qua MockMvc. 3. UserController gọi tiếp UserService.updateProfile(). 4. UserService lưu các thay đổi thông qua UserRepository.save(). 5. Tải lại GET /api/user/me hoặc truy vấn DB để xác nhận tính bền vững. | D13: HTTP status là 200 OK. Các trường đã cập nhật được lưu trong DB. | E13: JWT hợp lệ và payload JSON hợp lệ. | F13: Đạt | G13: 2026-08-07 | H13: phongdx | I13: Đạt | J13: 2026-08-07 | K13: phongdx | L13: Đạt | M13: 2026-08-07 | N13: phongdx | O13: ĐƯA tôi HTTP 200
A14: IT_USER_03 | B14: Xác minh lỗi xác thực trên payload hồ sơ không hợp lệ. | C14: 1. Đăng nhập và lấy JWT. 2. Gọi PUT hoặc PATCH /api/user/me với trường không hợp lệ (ví dụ: định dạng email sai) qua MockMvc. 3. UserController kích hoạt xác thực đậu trước khi UserService lưu. 4. Xác nhận hàng UserRepository không thay đổi. | D14: HTTP status là 400 Yêu cầu không hợp lệ. Lỗi cho biết trường không hợp lệ. Hồ sơ DB không thay đổi. | E14: Hợp lệ JWT. | F14: Đạt | G14: 2026-08-07 | H14: phongdx | I14: Đạt | J14: 2026-08-07 | K14: phongdx | L14: Đạt | M14: 2026-08-07 | N14: phongdx | O14: sai mật khẩu hiện tại HTTP 400
A15: IT_USER_04 | B15: Xác minh quyền truy cập hồ sơ chưa được xác thực bị từ chối qua Controller. | C15: 1. Gọi GET /api/user/me qua MockMvc (không cần xác thực). 2. Bộ lọc bảo mật từ chối cuộc gọi trước UserController và UserService. | D15: HTTP status là 401 hoặc 403. | E15: Không. | F15: Đạt | G15: 2026-08-07 | H15: phongdx | I15: Đạt | J15: 2026-08-07 | K15: phongdx | L15: Đạt | M15: 2026-08-07 | N15: phongdx | O15: điểm cuối hình đại diện có dây HTTP 400

Sheet IT_CLASS
A2: Chức năng (Feature) | B2: Quản lý lớp học | R2: Passed
A3: Yêu cầu kiểm thử | B3: IT cho lớp học nhân viên CRUD (Controller-Service-Repository). | R3: Failed
A4: Số lượng TC | B4: =COUNTIF(A11:A1000,"IT_*") | R4: Pending
A5: Vòng kiểm thử | B5: Đạt | C5: Không đạt | D5: Chờ | E5: Không áp dụng | R5: N/A
A6: Vòng 1 | B6: =COUNTIF($F11:$F991,B5) | C6: =COUNTIF($F11:$F991,C5) | D6: =COUNTIF($F11:$F991,D5) | E6: =COUNTIF($F11:$F991,E5)
A7: Vòng 2 | B7: =COUNTIF($I11:$I991,B5) | C7: =COUNTIF($I11:$I991,C5) | D7: =COUNTIF($I11:$I991,D5) | E7: =COUNTIF($I11:$I991,E5)
A8: Vòng 3 | B8: =COUNTIF($L11:$L991,B5) | C8: =COUNTIF($L11:$L991,C5) | D8: =COUNTIF($L11:$L991,D5) | E8: =COUNTIF($L11:$L991,E5)
A10: Mã Test Case | B10: Mô tả Test Case | C10: Các bước thực hiện | D10: Kết quả mong đợi | E10: Tiền điều kiện | F10: Vòng 1 | G10: Ngày test | H10: Người test | I10: Vòng 2 | J10: Ngày test | K10: Người test | L10: Vòng 3 | M10: Ngày test | N10: Người test | O10: Ghi chú
A11: Xem danh sách lớp học
A12: IT_CLASS_01 | B12: Xác minh danh sách nhân viên các lớp học thông qua Kiểm soát viên. | C12: 1. Đăng nhập bằng STAFF và nhận JWT. 2. Gọi GET /api/staff/classrooms qua MockMvc bằng mã thông báo Bearer. 3. StaffClassroomController gọi tiếp ClassroomOfferingService.list(). 4. ClassroomOfferingService đọc ClassroomOfferingRepository. | D12: HTTP status là 200 OK. JSON chứa danh sách các dịch vụ của lớp học. | E12: STAFF JWT có sẵn. Ít nhất một lớp học tồn tại. | F12: Đạt | G12: 2026-08-07 | H12: phongdx | I12: Đạt | J12: 2026-08-07 | K12: phongdx | L12: Đạt | M12: 2026-08-07 | N12: phongdx | O12: phòng học của nhân viên HTTP 200
A13: Tạo lớp học
A14: IT_CLASS_02 | B14: Xác minh nhân viên tạo đề xuất lớp học qua Controller (tạo quy trình). | C14: 1. Đăng nhập bằng STAFF và nhận JWT. 2. Gọi GET /api/staff/classrooms/training-programs để chọn id Chương trình đào tạo đã xuất bản. 3. Gọi POST /api/staff/classroom-proposals với tiêu đề, CourseOfferingId, dung lượng, ngày, ngày trong tuần, thời gian phiên qua MockMvc. 4. StaffClassroomProposalController gọi tiếp ClassroomProposalService.create(); đề xuất dự thảo được lưu. Lưu ý: StaffClassroomController không có tạo gốc POST /api/staff/classrooms; mở một lớp đi qua đề nghị phê duyệt. | D14: HTTP status là 200 hoặc 201. JSON chứa id đề xuất vàphê duyệtStatus=DRAFT (hoặc tương đương). | E14: Đã xuất bản Chương trình đào tạo và STAFF JWT. | F14: Đạt | G14: 2026-08-07 | H14: phongdx | I14: Đạt | J14: 2026-08-07 | K14: phongdx | L14: Đạt | M14: 2026-08-07 | N14: phongdx | O14: đề xuất lớp học tạo HTTP 200
A15: Cập nhật lớp học
A16: IT_CLASS_03 | B16: Xác minh nhân viên cập nhật lớp học qua Controller. | C16: 1. Đăng nhập bằng STAFF và nhận JWT. 2. Gọi GET /api/staff/classrooms và chọn id ưu đãi có thể cập nhật (thích NGOẠI TUYẾN mà không có chương trình giảng dạy chưa được phê duyệt). 3. Gọi PUT /api/staff/classrooms/{id} với phần thân CreateClassroomOfferingRequest hợp lệ thông qua MockMvc. 4. StaffClassroomController gọi tiếp ClassroomOfferingService.updateOffering(). 5. ClassroomOfferingService lưu các thay đổi thông qua ClassroomOfferingRepository. | D16: HTTP status là 200 OK. Các trường đã cập nhật được lưu trong DB. | E16: Hiện có sẵn id lớp học có thể cập nhật. | F16: Đạt | G16: 2026-08-07 | H16: phongdx | I16: Đạt | J16: 2026-08-07 | K16: phongdx | L16: Đạt | M16: 2026-08-07 | N16: phongdx | O16: cập nhật lớp học của nhân viên HTTP 200

Sheet IT_ASNTEACH
A2: Chức năng (Feature) | B2: Phân công giáo viên vào lớp | R2: Passed
A3: Yêu cầu kiểm thử | B3: IT cho nhân viên phân công giáo viên vào lớp (Controller-Service-Repository). | R3: Failed
A4: Số lượng TC | B4: =COUNTIF(A11:A1000,"IT_*") | R4: Pending
A5: Vòng kiểm thử | B5: Đạt | C5: Không đạt | D5: Chờ | E5: Không áp dụng | R5: N/A
A6: Vòng 1 | B6: =COUNTIF($F11:$F933,B5) | C6: =COUNTIF($F11:$F933,C5) | D6: =COUNTIF($F11:$F933,D5) | E6: =COUNTIF($F11:$F933,E5)
A7: Vòng 2 | B7: =COUNTIF($I11:$I933,B5) | C7: =COUNTIF($I11:$I933,C5) | D7: =COUNTIF($I11:$I933,D5) | E7: =COUNTIF($I11:$I933,E5)
A8: Vòng 3 | B8: =COUNTIF($L11:$L933,B5) | C8: =COUNTIF($L11:$L933,C5) | D8: =COUNTIF($L11:$L933,D5) | E8: =COUNTIF($L11:$L933,E5)
A10: Mã Test Case | B10: Mô tả Test Case | C10: Các bước thực hiện | D10: Kết quả mong đợi | E10: Tiền điều kiện | F10: Vòng 1 | G10: Ngày test | H10: Người test | I10: Vòng 2 | J10: Ngày test | K10: Người test | L10: Vòng 3 | M10: Ngày test | N10: Người test | O10: Ghi chú
A11: Phân công giáo viên vào lớp
A12: IT_ASNTEACH_01 | B12: Xác minh việc phân công giáo viên vào lớp qua Controller. | C12: 1. Đăng nhập bằng STAFF và nhận JWT. 2. Gọi POST /api/staff/classrooms/{id}/teachers/{teacherId}/assign qua MockMvc. 3. StaffClassroomController gọi tiếp ClassroomOfferingService.assignTeacher(). 4. ClassroomOfferingService viết ClassroomTeacherAssignmentRepository. | D12: HTTP status là 200 hoặc 201. Đã có hàng phân công của giáo viên cho lớp học. | E12: Lớp học và người dùng TEACHER tồn tại. | F12: Đạt | G12: 2026-08-07 | H12: phongdx | I12: Đạt | J12: 2026-08-07 | K12: phongdx | L12: Đạt | M12: 2026-08-07 | N12: phongdx | O12: chỉ định giáo viên HTTP 200
A13: IT_ASNTEACH_02 | B13: Xác minh giáo viên phân công bị từ chối đối với những người không phải là nhân viên qua Controller. | C13: 1. Đăng nhập bằng LEARNER và nhận JWT. 2. Gọi POST /api/staff/classrooms/{id}/teachers/{teacherId}/assign qua MockMvc. 3. Bảo mật hoặc StaffClassroomController từ chối cuộc gọi trước khi ghi dịch vụ. 4. Xác nhận ClassroomTeacherAssignmentRepository không có hàng mới. | D13: HTTP status là 403. Không có hàng phân công nào được tạo. | E13: Lớp học tồn tại. | F13: Đạt | G13: 2026-08-07 | H13: phongdx | I13: Đạt | J13: 2026-08-07 | K13: phongdx | L13: Đạt | M13: 2026-08-07 | N13: phongdx | O13: người học bị chặn chỉ định giáo viên HTTP 403

Sheet IT_SCHEDULE
A2: Chức năng (Feature) | B2: Xem lịch giảng dạy | R2: Passed
A3: Yêu cầu kiểm thử | B3: IT cho lịch giảng dạy của giáo viên/lớp học được phân công (Controller-Service-Repository). | R3: Failed
A4: Số lượng TC | B4: =COUNTIF(A11:A1000,"IT_*") | R4: Pending
A5: Vòng kiểm thử | B5: Đạt | C5: Không đạt | D5: Chờ | E5: Không áp dụng | R5: N/A
A6: Vòng 1 | B6: =COUNTIF($F11:$F991,B5) | C6: =COUNTIF($F11:$F991,C5) | D6: =COUNTIF($F11:$F991,D5) | E6: =COUNTIF($F11:$F991,E5)
A7: Vòng 2 | B7: =COUNTIF($I11:$I991,B5) | C7: =COUNTIF($I11:$I991,C5) | D7: =COUNTIF($I11:$I991,D5) | E7: =COUNTIF($I11:$I991,E5)
A8: Vòng 3 | B8: =COUNTIF($L11:$L991,B5) | C8: =COUNTIF($L11:$L991,C5) | D8: =COUNTIF($L11:$L991,D5) | E8: =COUNTIF($L11:$L991,E5)
A10: Mã Test Case | B10: Mô tả Test Case | C10: Các bước thực hiện | D10: Kết quả mong đợi | E10: Tiền điều kiện | F10: Vòng 1 | G10: Ngày test | H10: Người test | I10: Vòng 2 | J10: Ngày test | K10: Người test | L10: Vòng 3 | M10: Ngày test | N10: Người test | O10: Ghi chú
A11: Xem lịch giảng dạy
A12: IT_SCHEDULE_01 | B12: Xác minh danh sách giáo viên được phân công qua Controller. | C12: 1. Đăng nhập bằng TEACHER và nhận JWT. 2. Gọi GET /api/teacher/classrooms/assigned qua MockMvc. 3. TeacherClassroomController gọi tiếp ClassroomOfferingService.listForTeacher(). 4. ClassroomOfferingService gán truy vấn và cung cấp kho lưu trữ. | D12: HTTP status là 200 OK. Chỉ những lớp học được giao cho giáo viên này mới được trả lại. | E12: TEACHER được chỉ định cho ít nhất một lớp học. | F12: Đạt | G12: 2026-08-07 | H12: phongdx | I12: Đạt | J12: 2026-08-07 | K12: phongdx | L12: Đạt | M12: 2026-08-07 | N12: phongdx | O12: giáo viên được giao
A13: IT_SCHEDULE_02 | B13: Xác minh giáo viên tải các buổi học qua Controller. | C13: 1. Đăng nhập bằng TEACHER và nhận JWT. 2. Gọi GET /api/teacher/classrooms/{id}/sessions qua MockMvc. 3. TeacherClassroomController gọi tiếp ClassroomOfferingService (phương pháp danh sách phiên). 4. Dịch vụ đọc ClassroomSessionRepository. | D13: HTTP status là 200 OK. Danh sách phiên khớp với DB cho sản phẩm đó. | E13: Lớp học được phân công có các buổi học. | F13: Đạt | G13: 2026-08-07 | H13: phongdx | I13: Đạt | J13: 2026-08-07 | K13: phongdx | L13: Đạt | M13: 2026-08-07 | N13: phongdx | O13: giáo viên được giao

Sheet IT_ATTEND
A2: Chức năng (Feature) | B2: Quản lý điểm danh lớp | R2: Passed
A3: Yêu cầu kiểm thử | B3: IT cho giáo viên xem/ghi lại việc tham dự lớp học (Controller-Service-Repository). | R3: Failed
A4: Số lượng TC | B4: =COUNTIF(A11:A1000,"IT_*") | R4: Pending
A5: Vòng kiểm thử | B5: Đạt | C5: Không đạt | D5: Chờ | E5: Không áp dụng | R5: N/A
A6: Vòng 1 | B6: =COUNTIF($F11:$F991,B5) | C6: =COUNTIF($F11:$F991,C5) | D6: =COUNTIF($F11:$F991,D5) | E6: =COUNTIF($F11:$F991,E5)
A7: Vòng 2 | B7: =COUNTIF($I11:$I991,B5) | C7: =COUNTIF($I11:$I991,C5) | D7: =COUNTIF($I11:$I991,D5) | E7: =COUNTIF($I11:$I991,E5)
A8: Vòng 3 | B8: =COUNTIF($L11:$L991,B5) | C8: =COUNTIF($L11:$L991,C5) | D8: =COUNTIF($L11:$L991,D5) | E8: =COUNTIF($L11:$L991,E5)
A10: Mã Test Case | B10: Mô tả Test Case | C10: Các bước thực hiện | D10: Kết quả mong đợi | E10: Tiền điều kiện | F10: Vòng 1 | G10: Ngày test | H10: Người test | I10: Vòng 2 | J10: Ngày test | K10: Người test | L10: Vòng 3 | M10: Ngày test | N10: Người test | O10: Ghi chú
A11: Ghi nhận điểm danh
A12: IT_ATTEND_01 | B12: Xác minh giáo viên lưu điểm tham dự phiên qua Controller. | C12: 1. Đăng nhập bằng TEACHER và nhận JWT. 2. Gọi POST /api/teacher/classrooms/attendance qua MockMvc với payload điểm danh (sessionId + trạng thái học viên). 3. TeacherClassroomController gọi tiếp ClassroomAttendanceService.saveAttendance(). 4. ClassroomAttendanceService nâng cấp các hàng trong ClassroomAttendanceRepository. | D12: HTTP status là 200 OK. Các hàng điểm danh được duy trì cho người học trong phiên học. | E12: Phiên tồn tại và giáo viên được ủy quyền. | F12: Đạt | G12: 2026-08-07 | H12: phongdx | I12: Đạt | J12: 2026-08-07 | K12: phongdx | L12: Đạt | M12: 2026-08-07 | N12: phongdx | O12: tham dự phiên HTTP 200
A13: Xem điểm danh
A14: IT_ATTEND_02 | B14: Xác minh giáo viên tải bảng chấm công qua Controller. | C14: 1. Đăng nhập bằng TEACHER và nhận JWT. 2. Gọi GET /api/teacher/classrooms/sessions/{sessionId}/attendance qua MockMvc. 3. TeacherClassroomController gọi tiếp ClassroomAttendanceService.getAttendance(). 4. ClassroomAttendanceService đọc ClassroomAttendanceRepository. | D14: HTTP status là 200 OK. JSON khớp với trạng thái tham dự được lưu trữ. | E14: Dữ liệu tham dự tồn tại. | F14: Đạt | G14: 2026-08-07 | H14: phongdx | I14: Đạt | J14: 2026-08-07 | K14: phongdx | L14: Đạt | M14: 2026-08-07 | N14: phongdx | O14: tham dự phiên HTTP 200

Sheet IT_MNGHW
A2: Chức năng (Feature) | B2: Quản lý bài tập (giáo viên) | R2: Passed
A3: Yêu cầu kiểm thử | B3: IT giúp giáo viên tạo bài tập về nhà và nộp bài (Controller-Service-Repository). Khác biệt với người học IT_HOMEWORK (UC-13 Gửi bài tập về nhà). | R3: Failed
A4: Số lượng TC | B4: =COUNTIF(A11:A1000,"IT_*") | R4: Pending
A5: Vòng kiểm thử | B5: Đạt | C5: Không đạt | D5: Chờ | E5: Không áp dụng | R5: N/A
A6: Vòng 1 | B6: =COUNTIF($F11:$F991,B5) | C6: =COUNTIF($F11:$F991,C5) | D6: =COUNTIF($F11:$F991,D5) | E6: =COUNTIF($F11:$F991,E5)
A7: Vòng 2 | B7: =COUNTIF($I11:$I991,B5) | C7: =COUNTIF($I11:$I991,C5) | D7: =COUNTIF($I11:$I991,D5) | E7: =COUNTIF($I11:$I991,E5)
A8: Vòng 3 | B8: =COUNTIF($L11:$L991,B5) | C8: =COUNTIF($L11:$L991,C5) | D8: =COUNTIF($L11:$L991,D5) | E8: =COUNTIF($L11:$L991,E5)
